Workbook

Sheet 00说明
A1: 《无名圣女》场景—卡牌—变量—结局总表 v0.3
A3: 一、这份工作簿解决什么
A4: 工作表 | B4: 用途
A5: 01知识状态 | B5: 逐场区分玩家、阿芸、阿禾及其他NPC分别知道什么，避免角色越过信息边界。
A6: 02选项编号 | B6: 为普通对话与关键回应分配唯一ID；数值列自动读取07数值索引。
A7: 03_S03卡牌组合 | B7: 列出3人物×3手段×2身份的18种组合，以及关键、普通、冲突与转化反馈。
A8: 04卡牌生命周期 | B8: 记录每张卡何时获得、翻面、被角色拒绝以及最终去向。
A9: 05_S05物品处置 | B9: 明确四件关键物的12种去向和5种终局行动。
A10: 06结局判定 | B10: 固定判定优先级和阈值，避免多个结局同时满足时随机落点。
A11: 07数值索引 | B11: 唯一数值源。后续调整承担、依赖、信任、追捕时只改这一张表。
A12: 08可达路径测试 | B12: 用公式验证每个结局至少有一条路径，并提供极端与边界路线。
A14: 二、四个隐藏变量如何理解
A15: 变量 | B15: 起点 | C15: 高分意味着 | D15: 低分意味着 | E15: 是否向玩家显示
A16: 承担 | B16: 0 | C16: 承认因果，并让证据与资源离开自己控制 | D16: 辩解、切割、继续把成本转给别人 | E16: 不显示
A17: 圣女依赖 | B17: 0 | C17: 越来越习惯用身份、信徒和神谕快速解决问题 | D17: 倾向以普通人身份承担较慢的行动 | E17: 不显示；通过UI华丽程度反馈
A18: 阿禾信任 | B18: 1 | C18: 相信当下的阿芸至少不会再次利用自己 | D18: 认为阿芸仍在控制信息和牺牲别人 | E18: 不显示；通过人物卡可用性反馈
A19: 追捕压力 | B19: 1 | C19: 身份暴露、停留过久，终局更可能死亡 | D19: 行动隐蔽，保留撤离空间 | E19: 不显示；通过马蹄、搜查与音效反馈
A21: 三、修改顺序
A22: 1 | B22: 先在07数值索引调整分值；不要直接改其他表的公式列。
A23: 2 | B23: 再到08可达路径测试查看结局是否仍全部可达。
A24: 4 | B24: 保持六个主场景；河滩/破祠堂、旧救济殿/纸扎铺使用子场景编号，避免既有选项与公式整体错位。
A25: 5 | B25: 原型优先实现S01—S03；S04—S05保留完整数据、对白任务与终局测试。
A26: 6 | B26: 正式对白由用户主笔；本表只规定剧情功能、认知边界、变量结果和禁止越界信息。
A28: 四、v0.3新增工作表
A29: 00A主线剧情节拍 | B29: 串联六个主场景、八个子场景的进入条件、目标、冲突、揭示与出口。
A30: 05A终局分流 | B30: 明确交给阿禾、交给接头人、亲自公开、自行保留四种证据路线。
A31: 08A前置合法性 | B31: 逐步检查接头暗号、阿禾接受条件、佩印条件与弃责条件，避免假PASS。
A32: 09对白写作任务 | B32: 标注用户需要主笔的对白段落、功能、认知边界和禁止写法。
A33: bug整理 | B33: 记录全部建议、评估结果、最终决策及落实位置。

Sheet 01知识状态
A1: 01｜逐场知识状态
A2: 原则：玩家知道≠主角知道；主角知道≠NPC知道。六个主场景可含子场景，所有信息必须有可见来源。
A4: 场次 | B4: 地点 | C4: 玩家当前知道 | D4: 阿芸当前知道 | E4: 阿禾当前知道 | F4: 沈婆当前知道 | G4: 老乞丐当前知道 | H4: 魏先当前知道
A5: S01-A | B5: 河滩 | C5: 阿芸从水中被拖出；一大一小两个身影争论是否救她 | D5: 身体沉重、失去姓名与来历；只能判断两人暂时没有杀意 | E5: 认出落水者仍有气；坚持救人 | F5: 未出场 | G5: 嫌麻烦但没有真正阻止阿禾 | H5: 只知道圣女坠河、藏物不见；尚未确认其生死
A6: S01-B | B6: 破祠堂 | C6: 阿芸失忆；河岸附近出现搜查者；她的呼吸和观察习惯异常熟练 | D6: 知道自己饥饿、受伤、害怕锣鼓与官差；不知道追兵为何而来 | E6: 救下陌生女人；察觉她不像普通流民；询问追兵是否在找她 | F6: 未出场 | G6: 看出她受过训练，只保留怀疑 | H6: 听属下汇报搜索结果，判断她若活着会寻找遮蔽与食物
A7: S02-A | B7: 县城／旧救济殿 | C7: 改址告示压住旧‘赐福供奉’告示；有人持旧粮牌被拒；告示角落有不寻常记号 | D7: 对县城贫困感到意外；不明白自己为何觉得这里本应富庶；对告示改动方式产生身体熟悉感 | E7: 知道沈婆住得偏远，可能不知道改址；疑惑阿芸为何熟悉旧救济殿 | F7: 尚不知道救济点已改；保留刘家旧粮牌 | G7: 认出改址记号与地下传递有关，但只说自己先去新救济点探路 | H7: 魏先判断阿芸若活着可能回旧活动区域，命人盯守新旧救济点
A8: S02-B | B8: 纸扎铺 | C8: 沈婆凭声音、站姿和动作认出阿芸；褪色圣女像仍被当作护佑；沈婆取出刘家旧粮牌 | D8: 怀疑自己与画像和圣女有关；掌握祭仪话术却不知道来源 | E8: 第一次看到沈婆跪拜；听见自己的全名‘刘家禾’与旧粮牌相连；开始警惕阿芸 | F8: 确认阿芸是曾来主持法会的圣女；仍相信她救过孙女 | G8: 不在场；无法通过阿禾描述提前知道纸扎铺发生的事 | H8: 沿河与旧救济殿布置搜查，尚未锁定纸扎铺
A9: S03 | B9: 临时救济点 | C9: 空锅、藏粮与圣女崇拜同时出现；玩家第一次用人物×手段×身份组合行动 | D9: 身体记得如何控制呼吸、停顿、视线和人群；获得美化记忆《金粥赐福》 | E9: 确认阿芸和圣女关系极深；根据她是否造神改变信任 | F9: 将任何有效救粮都解释为圣女显灵 | G9: 在藏粮封签上再次看见改址记号；行动结束后给出半张仓单与不完整暗号 | H9: 通过‘圣女归来’或粮仓骚动缩小搜索范围
A10: S04 | B10: 旧救济殿后室 | C10: 旧粮牌指向封存赈籍；名单显示刘家因未缴供奉被除名；记忆翻为《锅底没有米》《被划掉的一家人》 | D10: 恢复主动划名与共犯罪责；知道失忆不能替自己免责；想起旧祈福台藏物位置 | E10: 确认弟弟病死、父亲抢粮被杀与除名直接相关；依据阿芸回应决定是否接受证据 | F10: 不在场；仍相信圣女回归能够修正一切 | G10: 知道名单与旧教团骗局；不替阿芸求情，只观察她是否交出控制权 | H10: 进入县城核心区域，判断阿芸已恢复部分记忆并会去取旧物
A11: S05 | B11: 旧祈福台 | C11: 玩家通过三步环境机关取回账簿、密函、银票和旧印；证据去向与终局行动分两阶段选择 | D11: 完整知道旧罪、藏物、魏先计划和旧权力入口；仍可选择交出、公开、保留或重新佩印 | E11: 知道阿芸罪责与四件旧物；高信任时协作撤离，中信任时只带证据离开，低信任时拒绝接手 | F11: 若被召来，只知道圣女与魏先发生冲突 | G11: 用半张仓单和对缝暗号验证接头渠道；只负责搭桥，不替任何人担保人格 | H11: 包围祈福台，试图夺回证据并把阿芸重新包装为叛教者或殉道者
A12: S06 | B12: 结局演出 | C12: 看到此前行为组合出的结果，而不是点击结局按钮 | D12: 依据路线承担、逃避、重新掌权或死亡 | E12: 依据路线同行、带证据离开、拒绝或在再次被利用时审判阿芸 | F12: 第二圣女路线中继续跪拜；其他路线未必获知全部真相 | G12: 保持旁观；接头路线只确认物品是否成功送出 | H12: 被击退、成功灭口或在聚众中失去控制，按路线结算

Sheet 02选项编号
A1: 02｜普通选项与关键回应编号
A2: 六个主场景：S01含河滩／破祠堂，S02含旧救济殿／纸扎铺，S03空锅卡牌组合，S04名单真相，S05旧物与终局行动，S06结局。
A4: 唯一编号 | B4: 场次 | C4: 触发问题 | D4: 玩家可见文本／行动 | E4: 设计意图 | F4: 承担 | G4: 圣女依赖 | H4: 阿禾信任 | I4: 追捕压力 | J4: 反馈
A5: S01-O01 | B5: S01 | C5: 阿禾问追兵是否在找她 | D5: 我不知道，但我不想连累你。 | E5: 坦白有限信息 | F5: =SUMIF('07数值索引'!$A$5:$A$56,A5,'07数值索引'!$D$5:$D$56) -> 0 | G5: =SUMIF('07数值索引'!$A$5:$A$56,A5,'07数值索引'!$E$5:$E$56) -> 0 | H5: =SUMIF('07数值索引'!$A$5:$A$56,A5,'07数值索引'!$F$5:$F$56) -> 1 | I5: =SUMIF('07数值索引'!$A$5:$A$56,A5,'07数值索引'!$G$5:$G$56) -> 0 | J5: 阿禾信任上升
A6: S01-O02 | B6: S01 | C6: 同上 | D6: 不是。一定是你看错了。 | E6: 否认与控制 | F6: =SUMIF('07数值索引'!$A$5:$A$56,A6,'07数值索引'!$D$5:$D$56) -> 0 | G6: =SUMIF('07数值索引'!$A$5:$A$56,A6,'07数值索引'!$E$5:$E$56) -> 0 | H6: =SUMIF('07数值索引'!$A$5:$A$56,A6,'07数值索引'!$F$5:$F$56) -> -1 | I6: =SUMIF('07数值索引'!$A$5:$A$56,A6,'07数值索引'!$G$5:$G$56) -> 0 | J6: 阿禾表面不问，暗中观察
A7: S01-O03 | B7: S01 | C7: 同上 | D7: 如果他们来了，你会把我交出去吗？ | E7: 试探 | F7: =SUMIF('07数值索引'!$A$5:$A$56,A7,'07数值索引'!$D$5:$D$56) -> 0 | G7: =SUMIF('07数值索引'!$A$5:$A$56,A7,'07数值索引'!$E$5:$E$56) -> 0 | H7: =SUMIF('07数值索引'!$A$5:$A$56,A7,'07数值索引'!$F$5:$F$56) -> 0 | I7: =SUMIF('07数值索引'!$A$5:$A$56,A7,'07数值索引'!$G$5:$G$56) -> 0 | J7: 暴露求生与察言观色本能
A8: S02-O01 | B8: S02 | C8: 沈婆跪拜 | D8: 让她起身，否认自己是圣女。 | E8: 拒绝身份 | F8: =SUMIF('07数值索引'!$A$5:$A$56,A8,'07数值索引'!$D$5:$D$56) -> 0 | G8: =SUMIF('07数值索引'!$A$5:$A$56,A8,'07数值索引'!$E$5:$E$56) -> 0 | H8: =SUMIF('07数值索引'!$A$5:$A$56,A8,'07数值索引'!$F$5:$F$56) -> 1 | I8: =SUMIF('07数值索引'!$A$5:$A$56,A8,'07数值索引'!$G$5:$G$56) -> 0 | J8: 阿禾稍微放松
A9: S02-O02 | B9: S02 | C9: 同上 | D9: 追问过去法会发生了什么。 | E9: 调查 | F9: =SUMIF('07数值索引'!$A$5:$A$56,A9,'07数值索引'!$D$5:$D$56) -> 0 | G9: =SUMIF('07数值索引'!$A$5:$A$56,A9,'07数值索引'!$E$5:$E$56) -> 0 | H9: =SUMIF('07数值索引'!$A$5:$A$56,A9,'07数值索引'!$F$5:$F$56) -> 0 | I9: =SUMIF('07数值索引'!$A$5:$A$56,A9,'07数值索引'!$G$5:$G$56) -> 0 | J9: 获得法会信息，不立即站队
A10: S02-O03 | B10: S02 | C10: 同上 | D10: 默认跪拜，以身份换取帮助。 | E10: 借用身份 | F10: =SUMIF('07数值索引'!$A$5:$A$56,A10,'07数值索引'!$D$5:$D$56) -> 0 | G10: =SUMIF('07数值索引'!$A$5:$A$56,A10,'07数值索引'!$E$5:$E$56) -> 1 | H10: =SUMIF('07数值索引'!$A$5:$A$56,A10,'07数值索引'!$F$5:$F$56) -> -1 | I10: =SUMIF('07数值索引'!$A$5:$A$56,A10,'07数值索引'!$G$5:$G$56) -> 1 | J10: 圣女依赖与暴露上升
A11: S04-A01 | B11: S04-A | C11: 阿禾问名单内容 | D11: 一张废名单。 | E11: 完整隐瞒 | F11: =SUMIF('07数值索引'!$A$5:$A$56,A11,'07数值索引'!$D$5:$D$56) -> -1 | G11: =SUMIF('07数值索引'!$A$5:$A$56,A11,'07数值索引'!$E$5:$E$56) -> 0 | H11: =SUMIF('07数值索引'!$A$5:$A$56,A11,'07数值索引'!$F$5:$F$56) -> -2 | I11: =SUMIF('07数值索引'!$A$5:$A$56,A11,'07数值索引'!$G$5:$G$56) -> 0 | J11: 阿禾开始核对每句话
A12: S04-A02 | B12: S04-A | C12: 同上 | D12: 和万清教有关，我还没看清。 | E12: 部分隐瞒 | F12: =SUMIF('07数值索引'!$A$5:$A$56,A12,'07数值索引'!$D$5:$D$56) -> 0 | G12: =SUMIF('07数值索引'!$A$5:$A$56,A12,'07数值索引'!$E$5:$E$56) -> 0 | H12: =SUMIF('07数值索引'!$A$5:$A$56,A12,'07数值索引'!$F$5:$F$56) -> -1 | I12: =SUMIF('07数值索引'!$A$5:$A$56,A12,'07数值索引'!$G$5:$G$56) -> 0 | J12: 仍保留最危险的部分
A13: S04-A03 | B13: S04-A | C13: 同上 | D13: 上面有你的名字。 | E13: 主动交代 | F13: =SUMIF('07数值索引'!$A$5:$A$56,A13,'07数值索引'!$D$5:$D$56) -> 1 | G13: =SUMIF('07数值索引'!$A$5:$A$56,A13,'07数值索引'!$E$5:$E$56) -> 0 | H13: =SUMIF('07数值索引'!$A$5:$A$56,A13,'07数值索引'!$F$5:$F$56) -> 1 | I13: =SUMIF('07数值索引'!$A$5:$A$56,A13,'07数值索引'!$G$5:$G$56) -> 0 | J13: 承担上升
A14: S04-A04 | B14: S04-A | C14: 同上 | D14: ......(沉默) 把名单交给阿禾。 | E14: 交出信息控制权 | F14: =SUMIF('07数值索引'!$A$5:$A$56,A14,'07数值索引'!$D$5:$D$56) -> 2 | G14: =SUMIF('07数值索引'!$A$5:$A$56,A14,'07数值索引'!$E$5:$E$56) -> 0 | H14: =SUMIF('07数值索引'!$A$5:$A$56,A14,'07数值索引'!$F$5:$F$56) -> 1 | I14: =SUMIF('07数值索引'!$A$5:$A$56,A14,'07数值索引'!$G$5:$G$56) -> 0 | J14: 不预设辩词（阿禾表情骤变）
A15: S04-B01 | B15: S04-B | C15: 阿禾逼问为何知道四口人 | D15: 那句话是我说的，名字也是我让人划掉的。 | E15: 完整承认 | F15: =SUMIF('07数值索引'!$A$5:$A$56,A15,'07数值索引'!$D$5:$D$56) -> 3 | G15: =SUMIF('07数值索引'!$A$5:$A$56,A15,'07数值索引'!$E$5:$E$56) -> 0 | H15: =SUMIF('07数值索引'!$A$5:$A$56,A15,'07数值索引'!$F$5:$F$56) -> 1 | I15: =SUMIF('07数值索引'!$A$5:$A$56,A15,'07数值索引'!$G$5:$G$56) -> 0 | J15: 不恢复原谅，只保留观察机会
A16: S04-B02 | B16: S04-B | C16: 同上 | D16: 是我说的，可我不知道最后会死人。 | E16: 部分辩解 | F16: =SUMIF('07数值索引'!$A$5:$A$56,A16,'07数值索引'!$D$5:$D$56) -> 0 | G16: =SUMIF('07数值索引'!$A$5:$A$56,A16,'07数值索引'!$E$5:$E$56) -> 0 | H16: =SUMIF('07数值索引'!$A$5:$A$56,A16,'07数值索引'!$F$5:$F$56) -> -1 | I16: =SUMIF('07数值索引'!$A$5:$A$56,A16,'07数值索引'!$G$5:$G$56) -> 0 | J16: 保留‘我没亲自动手’的自我保护
... A23: ACT-BETRAY | B23: S05 | C23: 同上 | D23: 谎称证据已送出，让阿禾拿空包引开追兵。 | E23: 再次利用 | F23: =SUMIF('07数值索引'!$A$5:$A$56,A23,'07数值索引'!$D$5:$D$56) -> -3 | G23: =SUMIF('07数值索引'!$A$5:$A$56,A23,'07数值索引'!$E$5:$E$56) -> 0 | H23: =SUMIF('07数值索引'!$A$5:$A$56,A23,'07数值索引'!$F$5:$F$56) -> -3 | I23: =SUMIF('07数值索引'!$A$5:$A$56,A23,'07数值索引'!$G$5:$G$56) -> 1 | J23: 满足条件时触发《审判》

Sheet 03_S03卡牌组合
A1: 03｜S03‘空锅前的神迹’有限卡牌组合
A3: 组合ID | B3: 人物卡 | C3: 手段卡 | D3: 身份卡 | E3: 级别 | F3: 系统反馈 | G3: 剧情结果／趣味反馈 | H3: 承担 | I3: 依赖 | J3: 信任 | K3: 追捕 | L3: 接头线索
A4: C-S03-A-F-R | B4: 阿禾 | C4: 少量食物 | D4: 无名流民 | E4: 关键 | F4: 可执行 | G4: 两人先救伤者和孩子；骚乱暂缓，但无法解决整体饥荒 | H4: =SUMIF('07数值索引'!$A$5:$A$56,A4,'07数值索引'!$D$5:$D$56) -> 1 | I4: =SUMIF('07数值索引'!$A$5:$A$56,A4,'07数值索引'!$E$5:$E$56) -> 0 | J4: =SUMIF('07数值索引'!$A$5:$A$56,A4,'07数值索引'!$F$5:$F$56) -> 1 | K4: =SUMIF('07数值索引'!$A$5:$A$56,A4,'07数值索引'!$G$5:$G$56) -> 0 | L4: =SUMIF('07数值索引'!$A$5:$A$56,A4,'07数值索引'!$M$5:$M$56) -> 0
A5: C-S03-A-I-R | B5: 阿禾 | C5: 藏粮消息 | D5: 无名流民 | E5: 关键 | F5: 可执行 | G5: 阿禾带人找到后院藏粮，粮商记住她的脸；封签出现与改址告示相同的记号 | H5: =SUMIF('07数值索引'!$A$5:$A$56,A5,'07数值索引'!$D$5:$D$56) -> 1 | I5: =SUMIF('07数值索引'!$A$5:$A$56,A5,'07数值索引'!$E$5:$E$56) -> 0 | J5: =SUMIF('07数值索引'!$A$5:$A$56,A5,'07数值索引'!$F$5:$F$56) -> 1 | K5: =SUMIF('07数值索引'!$A$5:$A$56,A5,'07数值索引'!$G$5:$G$56) -> 1 | L5: =SUMIF('07数值索引'!$A$5:$A$56,A5,'07数值索引'!$M$5:$M$56) -> 1
A6: C-S03-A-P-R | B6: 阿禾 | C6: 褪色圣女像 | D6: 无名流民 | E6: 冲突 | F6: 拒绝后重选 | G6: 阿禾把画像推回去：‘纸上的人又不会搬粮。’ | H6: =SUMIF('07数值索引'!$A$5:$A$56,A6,'07数值索引'!$D$5:$D$56) -> 0 | I6: =SUMIF('07数值索引'!$A$5:$A$56,A6,'07数值索引'!$E$5:$E$56) -> 0 | J6: =SUMIF('07数值索引'!$A$5:$A$56,A6,'07数值索引'!$F$5:$F$56) -> 0 | K6: =SUMIF('07数值索引'!$A$5:$A$56,A6,'07数值索引'!$G$5:$G$56) -> 0 | L6: =SUMIF('07数值索引'!$A$5:$A$56,A6,'07数值索引'!$M$5:$M$56) -> 0
A7: C-S03-A-F-P | B7: 阿禾 | C7: 少量食物 | D7: 画像中的女人 | E7: 普通 | F7: 可执行 | G7: 阿芸以训练过的声音维持秩序，阿禾分粮；救助变快，但阿禾开始警惕 | H7: =SUMIF('07数值索引'!$A$5:$A$56,A7,'07数值索引'!$D$5:$D$56) -> 1 | I7: =SUMIF('07数值索引'!$A$5:$A$56,A7,'07数值索引'!$E$5:$E$56) -> 1 | J7: =SUMIF('07数值索引'!$A$5:$A$56,A7,'07数值索引'!$F$5:$F$56) -> 0 | K7: =SUMIF('07数值索引'!$A$5:$A$56,A7,'07数值索引'!$G$5:$G$56) -> 1 | L7: =SUMIF('07数值索引'!$A$5:$A$56,A7,'07数值索引'!$M$5:$M$56) -> 0
A8: C-S03-A-I-P | B8: 阿禾 | C8: 藏粮消息 | D8: 画像中的女人 | E8: 关键 | F8: 可执行 | G8: 阿芸把真实消息说成预言；阿禾只负责开门，不肯替她作证；封签记号被老乞丐认出 | H8: =SUMIF('07数值索引'!$A$5:$A$56,A8,'07数值索引'!$D$5:$D$56) -> 1 | I8: =SUMIF('07数值索引'!$A$5:$A$56,A8,'07数值索引'!$E$5:$E$56) -> 1 | J8: =SUMIF('07数值索引'!$A$5:$A$56,A8,'07数值索引'!$F$5:$F$56) -> 0 | K8: =SUMIF('07数值索引'!$A$5:$A$56,A8,'07数值索引'!$G$5:$G$56) -> 2 | L8: =SUMIF('07数值索引'!$A$5:$A$56,A8,'07数值索引'!$M$5:$M$56) -> 1
A9: C-S03-A-P-P | B9: 阿禾 | C9: 褪色圣女像 | D9: 画像中的女人 | E9: 冲突 | F9: 拒绝后重选 | G9: 阿禾拒绝扮演神迹见证人，人物卡弹回 | H9: =SUMIF('07数值索引'!$A$5:$A$56,A9,'07数值索引'!$D$5:$D$56) -> 0 | I9: =SUMIF('07数值索引'!$A$5:$A$56,A9,'07数值索引'!$E$5:$E$56) -> 0 | J9: =SUMIF('07数值索引'!$A$5:$A$56,A9,'07数值索引'!$F$5:$F$56) -> 0 | K9: =SUMIF('07数值索引'!$A$5:$A$56,A9,'07数值索引'!$G$5:$G$56) -> 0 | L9: =SUMIF('07数值索引'!$A$5:$A$56,A9,'07数值索引'!$M$5:$M$56) -> 0
A10: C-S03-S-F-R | B10: 沈婆 | C10: 少量食物 | D10: 无名流民 | E10: 普通 | F10: 可执行 | G10: 沈婆凭熟人关系组织排队，食物仍然不够 | H10: =SUMIF('07数值索引'!$A$5:$A$56,A10,'07数值索引'!$D$5:$D$56) -> 1 | I10: =SUMIF('07数值索引'!$A$5:$A$56,A10,'07数值索引'!$E$5:$E$56) -> 0 | J10: =SUMIF('07数值索引'!$A$5:$A$56,A10,'07数值索引'!$F$5:$F$56) -> 0 | K10: =SUMIF('07数值索引'!$A$5:$A$56,A10,'07数值索引'!$G$5:$G$56) -> 0 | L10: =SUMIF('07数值索引'!$A$5:$A$56,A10,'07数值索引'!$M$5:$M$56) -> 0
A11: C-S03-S-I-R | B11: 沈婆 | C11: 藏粮消息 | D11: 无名流民 | E11: 普通 | F11: 可执行 | G11: 沈婆以纸扎铺老板身份作证；开仓后发现带记号的封签，老乞丐确认其与转运网有关 | H11: =SUMIF('07数值索引'!$A$5:$A$56,A11,'07数值索引'!$D$5:$D$56) -> 1 | I11: =SUMIF('07数值索引'!$A$5:$A$56,A11,'07数值索引'!$E$5:$E$56) -> 0 | J11: =SUMIF('07数值索引'!$A$5:$A$56,A11,'07数值索引'!$F$5:$F$56) -> 0 | K11: =SUMIF('07数值索引'!$A$5:$A$56,A11,'07数值索引'!$G$5:$G$56) -> 1 | L11: =SUMIF('07数值索引'!$A$5:$A$56,A11,'07数值索引'!$M$5:$M$56) -> 1
A12: C-S03-S-P-R | B12: 沈婆 | C12: 褪色圣女像 | D12: 无名流民 | E12: 转化 | F12: 确认后重选 | G12: 阿芸否认身份，沈婆却先跪下；系统询问是否接受《画像中的女人》 | H12: =SUMIF('07数值索引'!$A$5:$A$56,A12,'07数值索引'!$D$5:$D$56) -> 0 | I12: =SUMIF('07数值索引'!$A$5:$A$56,A12,'07数值索引'!$E$5:$E$56) -> 1 | J12: =SUMIF('07数值索引'!$A$5:$A$56,A12,'07数值索引'!$F$5:$F$56) -> -1 | K12: =SUMIF('07数值索引'!$A$5:$A$56,A12,'07数值索引'!$G$5:$G$56) -> 1 | L12: =SUMIF('07数值索引'!$A$5:$A$56,A12,'07数值索引'!$M$5:$M$56) -> 0
A13: C-S03-S-F-P | B13: 沈婆 | C13: 少量食物 | D13: 画像中的女人 | E13: 普通 | F13: 可执行 | G13: 沈婆高喊赐福，少量食物被包装成圣女回归的证明 | H13: =SUMIF('07数值索引'!$A$5:$A$56,A13,'07数值索引'!$D$5:$D$56) -> 1 | I13: =SUMIF('07数值索引'!$A$5:$A$56,A13,'07数值索引'!$E$5:$E$56) -> 1 | J13: =SUMIF('07数值索引'!$A$5:$A$56,A13,'07数值索引'!$F$5:$F$56) -> -1 | K13: =SUMIF('07数值索引'!$A$5:$A$56,A13,'07数值索引'!$G$5:$G$56) -> 1 | L13: =SUMIF('07数值索引'!$A$5:$A$56,A13,'07数值索引'!$M$5:$M$56) -> 0
A14: C-S03-S-I-P | B14: 沈婆 | C14: 藏粮消息 | D14: 画像中的女人 | E14: 核心 | F14: 可执行 | G14: 阿芸把情报包装成神谕逼粮商开仓；救人最多、暴露最大，并发现接头标记 | H14: =SUMIF('07数值索引'!$A$5:$A$56,A14,'07数值索引'!$D$5:$D$56) -> 0 | I14: =SUMIF('07数值索引'!$A$5:$A$56,A14,'07数值索引'!$E$5:$E$56) -> 2 | J14: =SUMIF('07数值索引'!$A$5:$A$56,A14,'07数值索引'!$F$5:$F$56) -> -1 | K14: =SUMIF('07数值索引'!$A$5:$A$56,A14,'07数值索引'!$G$5:$G$56) -> 2 | L14: =SUMIF('07数值索引'!$A$5:$A$56,A14,'07数值索引'!$M$5:$M$56) -> 1
A15: C-S03-S-P-P | B15: 沈婆 | C15: 褪色圣女像 | D15: 画像中的女人 | E15: 关键 | F15: 可执行 | G15: 沈婆认主，人群随之跪拜；阿芸一句话尚未说，秩序已属于她 | H15: =SUMIF('07数值索引'!$A$5:$A$56,A15,'07数值索引'!$D$5:$D$56) -> 0 | I15: =SUMIF('07数值索引'!$A$5:$A$56,A15,'07数值索引'!$E$5:$E$56) -> 2 | J15: =SUMIF('07数值索引'!$A$5:$A$56,A15,'07数值索引'!$F$5:$F$56) -> -1 | K15: =SUMIF('07数值索引'!$A$5:$A$56,A15,'07数值索引'!$G$5:$G$56) -> 2 | L15: =SUMIF('07数值索引'!$A$5:$A$56,A15,'07数值索引'!$M$5:$M$56) -> 0
... A21: C-S03-O-P-P | B21: 老乞丐 | C21: 褪色圣女像 | D21: 画像中的女人 | E21: 冲突 | F21: 拒绝后重选 | G21: 老乞丐拒绝登台：‘我看过三位圣女，纸做的最耐活。’ | H21: =SUMIF('07数值索引'!$A$5:$A$56,A21,'07数值索引'!$D$5:$D$56) -> 0 | I21: =SUMIF('07数值索引'!$A$5:$A$56,A21,'07数值索引'!$E$5:$E$56) -> 0 | J21: =SUMIF('07数值索引'!$A$5:$A$56,A21,'07数值索引'!$F$5:$F$56) -> 0 | K21: =SUMIF('07数值索引'!$A$5:$A$56,A21,'07数值索引'!$G$5:$G$56) -> 0 | L21: =SUMIF('07数值索引'!$A$5:$A$56,A21,'07数值索引'!$M$5:$M$56) -> 0

Sheet 04卡牌生命周期
A1: 04｜卡牌生命周期
A3: 卡牌ID | B3: 类别 | C3: 卡名 | D3: 首次获得 | E3: 翻面／强化 | F3: 拒绝条件 | G3: 最终去向 | H3: 设计作用 | I3: Demo状态
A4: ID-01 | B4: 身份 | C4: 《无名流民》 | D4: S01醒来后 | E4: S01—S05始终可用 | F4: 无 | G4: S05仍可用于普通人行动 | H4: 代表低效率但不支配他人的方法 | I4: 常驻
A5: ID-02 | B5: 身份 | C5: 《画像中的女人》 | D5: S02被沈婆认出后 | E5: S03接受认主或S04强制确认 | F5: 阿禾拒绝为其扮演神迹见证人 | G5: 翻为《万清圣女》 | H5: 身份悬念的中间态 | I5: 常驻至翻面
A6: ID-03 | B6: 身份 | C6: 《万清圣女》 | D6: S03可选解锁；S04必然解锁 | E6: 佩戴旧印后强化 | F6: 高信任阿禾仍拒绝替她造神 | G6: 重新掌权／拒绝使用／死亡 | H6: 越好用，越危险 | I6: 分支核心
A7: CH-01 | B7: 人物 | C7: 《阿禾》 | D7: S01救助后 | E7: 信任随选择变化 | F7: S03拒绝圣女画像组合；信任过低拒绝带证据 | G7: 同行／离开／审判阿芸 | H7: 人物卡不是工具 | I7: 常驻
A8: CH-02 | B8: 人物 | C8: 《纸扎铺的沈婆》 | D8: S02完成认主 | E8: 使用圣女身份时影响力增强 | F8: 不会拒绝圣女组合；会误读真相为神迹 | G8: 第二圣女路线继续跪拜 | H8: 展示信徒为何需要圣女 | I8: S02起可用
A9: CH-03 | B9: 人物 | C9: 《老乞丐》 | D9: S01开场前已与阿禾相互照应一段时间；S03成为可用卡 | E9: 调查藏粮后以半张仓单验证接头渠道 | F9: 拒绝画像与登台组合 | G9: 旁观／提供渠道／不替主角赎罪 | H9: 冷幽默、底层经验与接头桥梁 | I9: S03可用
A10: CH-04 | B10: 人物 | C10: 《唐姓接头人》 | D10: S03调查藏粮后，由老乞丐用仓单与暗号验证 | E10: 无升级；只证明身份和转运能力，不证明道德可靠 | F10: 未取得完整暗号时卡牌不出现 | G10: 接收账簿／密函并送出县城 | H10: 结构性行动渠道，不扩写个人支线 | I10: 条件卡
A11: MT-01 | B11: 手段 | C11: 《少量食物》 | D11: S03进入赈济点 | E11: 使用后消耗 | F11: 无角色拒绝食物本身 | G11: 救少数人／参与神迹包装 | H11: 有限资源制造真实取舍 | I11: S03消耗
A12: MT-02 | B12: 手段 | C12: 《藏粮消息》 | D12: S03观察或老乞丐提示 | E12: 可与身份组合成为‘预言’ | F12: 无；但人物承担风险不同 | G12: 开仓／取得接头线索 | H12: 事实可被诚实使用，也可被包装成神谕 | I12: S03使用
A13: MT-03 | B13: 手段 | C13: 《褪色圣女像》 | D13: S02纸扎铺 | E13: 与身份卡组合放大认主 | F13: 阿禾与老乞丐拒绝参与造神 | G13: 成为信仰媒介／被收回 | H13: 测试人物主体性 | I13: S03使用
A14: MEM-01 | B14: 记忆 | C14: 《金粥赐福》 | D14: S03空锅触发 | E14: S04翻面 | F14: 无 | G14: 翻为《锅底没有米》 | H14: 先给玩家善意解释，再收回 | I14: 翻面
... A20: PR-01 | B20: 剧情道具 | C20: 《刘家旧粮牌》 | D20: S02-B沈婆取出 | E20: S03被新救济点管事拒绝 | F20: 不进入组合槽 | G20: S04指向旧赈籍与除名记录 | H20: 解释为何返回旧救济殿；种下刘家全名 | I20: 叙事道具

Sheet 05_S05物品处置
A1: 05｜S05关键物处置与终局行动
A2: 第一阶段逐一处理账簿、密函、银票与旧印；第二阶段处理魏先追至后的眼前行动。物品去向不会自动等于结局。
A4: 选项ID | B4: 关键物 | C4: 去向 | D4: 可用条件 | E4: 叙事结果 | F4: 承担 | G4: 依赖 | H4: 信任 | I4: 追捕 | J4: 证据送出 | K4: 证据私藏 | L4: 带走银票 | M4: 接头线索
A5: K-LDG-AHE | B5: 秘密账簿 | C5: 交给阿禾 | D5: 信任≥4；或信任1—3且此前S04-A04/S04-B01 | E5: 高信任时协作撤离；中信任时阿禾只带证据离开；低信任拒绝 | F5: =SUMIF('07数值索引'!$A$5:$A$80,$A5,'07数值索引'!$D$5:$D$80) -> 2 | G5: =SUMIF('07数值索引'!$A$5:$A$80,$A5,'07数值索引'!$E$5:$E$80) -> 0 | H5: =SUMIF('07数值索引'!$A$5:$A$80,$A5,'07数值索引'!$F$5:$F$80) -> 1 | I5: =SUMIF('07数值索引'!$A$5:$A$80,$A5,'07数值索引'!$G$5:$G$80) -> 0 | J5: =SUMIF('07数值索引'!$A$5:$A$80,$A5,'07数值索引'!$H$5:$H$80) -> 1 | K5: =SUMIF('07数值索引'!$A$5:$A$80,$A5,'07数值索引'!$I$5:$I$80) -> 0 | L5: =SUMIF('07数值索引'!$A$5:$A$80,$A5,'07数值索引'!$J$5:$J$80) -> 0 | M5: =SUMIF('07数值索引'!$A$5:$A$80,$A5,'07数值索引'!$M$5:$M$80) -> 0
A6: K-LDG-REB | B6: 秘密账簿 | C6: 交给接头人 | D6: 已通过老乞丐获得完整暗号 | E6: 证据进入结构性行动；主角不自动获得组织接纳 | F6: =SUMIF('07数值索引'!$A$5:$A$80,$A6,'07数值索引'!$D$5:$D$80) -> 2 | G6: =SUMIF('07数值索引'!$A$5:$A$80,$A6,'07数值索引'!$E$5:$E$80) -> 0 | H6: =SUMIF('07数值索引'!$A$5:$A$80,$A6,'07数值索引'!$F$5:$F$80) -> 0 | I6: =SUMIF('07数值索引'!$A$5:$A$80,$A6,'07数值索引'!$G$5:$G$80) -> 0 | J6: =SUMIF('07数值索引'!$A$5:$A$80,$A6,'07数值索引'!$H$5:$H$80) -> 1 | K6: =SUMIF('07数值索引'!$A$5:$A$80,$A6,'07数值索引'!$I$5:$I$80) -> 0 | L6: =SUMIF('07数值索引'!$A$5:$A$80,$A6,'07数值索引'!$J$5:$J$80) -> 0 | M6: =SUMIF('07数值索引'!$A$5:$A$80,$A6,'07数值索引'!$M$5:$M$80) -> 1
A7: K-LDG-PUB | B7: 秘密账簿 | C7: 阿芸亲自公开 | D7: 已取得账簿 | E7: 证据公开，但解释权仍可能被圣女身份垄断 | F7: =SUMIF('07数值索引'!$A$5:$A$80,$A7,'07数值索引'!$D$5:$D$80) -> 1 | G7: =SUMIF('07数值索引'!$A$5:$A$80,$A7,'07数值索引'!$E$5:$E$80) -> 2 | H7: =SUMIF('07数值索引'!$A$5:$A$80,$A7,'07数值索引'!$F$5:$F$80) -> 0 | I7: =SUMIF('07数值索引'!$A$5:$A$80,$A7,'07数值索引'!$G$5:$G$80) -> 1 | J7: =SUMIF('07数值索引'!$A$5:$A$80,$A7,'07数值索引'!$H$5:$H$80) -> 1 | K7: =SUMIF('07数值索引'!$A$5:$A$80,$A7,'07数值索引'!$I$5:$I$80) -> 0 | L7: =SUMIF('07数值索引'!$A$5:$A$80,$A7,'07数值索引'!$J$5:$J$80) -> 0 | M7: =SUMIF('07数值索引'!$A$5:$A$80,$A7,'07数值索引'!$M$5:$M$80) -> 0
A8: K-LDG-KEEP | B8: 秘密账簿 | C8: 自行保留 | D8: 无 | E8: 继续作为自保、勒索、销毁或逃亡筹码 | F8: =SUMIF('07数值索引'!$A$5:$A$80,$A8,'07数值索引'!$D$5:$D$80) -> -2 | G8: =SUMIF('07数值索引'!$A$5:$A$80,$A8,'07数值索引'!$E$5:$E$80) -> 0 | H8: =SUMIF('07数值索引'!$A$5:$A$80,$A8,'07数值索引'!$F$5:$F$80) -> 0 | I8: =SUMIF('07数值索引'!$A$5:$A$80,$A8,'07数值索引'!$G$5:$G$80) -> 0 | J8: =SUMIF('07数值索引'!$A$5:$A$80,$A8,'07数值索引'!$H$5:$H$80) -> 0 | K8: =SUMIF('07数值索引'!$A$5:$A$80,$A8,'07数值索引'!$I$5:$I$80) -> 1 | L8: =SUMIF('07数值索引'!$A$5:$A$80,$A8,'07数值索引'!$J$5:$J$80) -> 0 | M8: =SUMIF('07数值索引'!$A$5:$A$80,$A8,'07数值索引'!$M$5:$M$80) -> 0
A9: K-LTR-AHE | B9: 裴家密函 | C9: 交给阿禾 | D9: 阿禾已接受账簿且仍在场 | E9: 把密函解释权也交给直接受害者 | F9: =SUMIF('07数值索引'!$A$5:$A$80,$A9,'07数值索引'!$D$5:$D$80) -> 2 | G9: =SUMIF('07数值索引'!$A$5:$A$80,$A9,'07数值索引'!$E$5:$E$80) -> 0 | H9: =SUMIF('07数值索引'!$A$5:$A$80,$A9,'07数值索引'!$F$5:$F$80) -> 1 | I9: =SUMIF('07数值索引'!$A$5:$A$80,$A9,'07数值索引'!$G$5:$G$80) -> 0 | J9: =SUMIF('07数值索引'!$A$5:$A$80,$A9,'07数值索引'!$H$5:$H$80) -> 1 | K9: =SUMIF('07数值索引'!$A$5:$A$80,$A9,'07数值索引'!$I$5:$I$80) -> 0 | L9: =SUMIF('07数值索引'!$A$5:$A$80,$A9,'07数值索引'!$J$5:$J$80) -> 0 | M9: =SUMIF('07数值索引'!$A$5:$A$80,$A9,'07数值索引'!$M$5:$M$80) -> 0
A10: K-LTR-REB | B10: 裴家密函 | C10: 交给接头人 | D10: 已获得完整暗号 | E10: 揭露裴家关系与殉道计划 | F10: =SUMIF('07数值索引'!$A$5:$A$80,$A10,'07数值索引'!$D$5:$D$80) -> 2 | G10: =SUMIF('07数值索引'!$A$5:$A$80,$A10,'07数值索引'!$E$5:$E$80) -> 0 | H10: =SUMIF('07数值索引'!$A$5:$A$80,$A10,'07数值索引'!$F$5:$F$80) -> 0 | I10: =SUMIF('07数值索引'!$A$5:$A$80,$A10,'07数值索引'!$G$5:$G$80) -> 0 | J10: =SUMIF('07数值索引'!$A$5:$A$80,$A10,'07数值索引'!$H$5:$H$80) -> 1 | K10: =SUMIF('07数值索引'!$A$5:$A$80,$A10,'07数值索引'!$I$5:$I$80) -> 0 | L10: =SUMIF('07数值索引'!$A$5:$A$80,$A10,'07数值索引'!$J$5:$J$80) -> 0 | M10: =SUMIF('07数值索引'!$A$5:$A$80,$A10,'07数值索引'!$M$5:$M$80) -> 1
A11: K-LTR-PUB | B11: 裴家密函 | C11: 阿芸亲自公开 | D11: 已解锁圣女身份 | E11: 真相公开，但公开方式可能再次造神 | F11: =SUMIF('07数值索引'!$A$5:$A$80,$A11,'07数值索引'!$D$5:$D$80) -> 0 | G11: =SUMIF('07数值索引'!$A$5:$A$80,$A11,'07数值索引'!$E$5:$E$80) -> 2 | H11: =SUMIF('07数值索引'!$A$5:$A$80,$A11,'07数值索引'!$F$5:$F$80) -> 0 | I11: =SUMIF('07数值索引'!$A$5:$A$80,$A11,'07数值索引'!$G$5:$G$80) -> 1 | J11: =SUMIF('07数值索引'!$A$5:$A$80,$A11,'07数值索引'!$H$5:$H$80) -> 1 | K11: =SUMIF('07数值索引'!$A$5:$A$80,$A11,'07数值索引'!$I$5:$I$80) -> 0 | L11: =SUMIF('07数值索引'!$A$5:$A$80,$A11,'07数值索引'!$J$5:$J$80) -> 0 | M11: =SUMIF('07数值索引'!$A$5:$A$80,$A11,'07数值索引'!$M$5:$M$80) -> 0
A12: K-LTR-KEEP | B12: 裴家密函 | C12: 自行保留 | D12: 无 | E12: 保留自保筹码，不让真相抵达他人 | F12: =SUMIF('07数值索引'!$A$5:$A$80,$A12,'07数值索引'!$D$5:$D$80) -> -1 | G12: =SUMIF('07数值索引'!$A$5:$A$80,$A12,'07数值索引'!$E$5:$E$80) -> 0 | H12: =SUMIF('07数值索引'!$A$5:$A$80,$A12,'07数值索引'!$F$5:$F$80) -> 0 | I12: =SUMIF('07数值索引'!$A$5:$A$80,$A12,'07数值索引'!$G$5:$G$80) -> 0 | J12: =SUMIF('07数值索引'!$A$5:$A$80,$A12,'07数值索引'!$H$5:$H$80) -> 0 | K12: =SUMIF('07数值索引'!$A$5:$A$80,$A12,'07数值索引'!$I$5:$I$80) -> 1 | L12: =SUMIF('07数值索引'!$A$5:$A$80,$A12,'07数值索引'!$J$5:$J$80) -> 0 | M12: =SUMIF('07数值索引'!$A$5:$A$80,$A12,'07数值索引'!$M$5:$M$80) -> 0
A13: K-SLV-VIC | B13: 三千两银票 | C13: 归还阿禾及受害者 | D13: 无 | E13: 迟到补偿，不兑换宽恕 | F13: =SUMIF('07数值索引'!$A$5:$A$80,$A13,'07数值索引'!$D$5:$D$80) -> 2 | G13: =SUMIF('07数值索引'!$A$5:$A$80,$A13,'07数值索引'!$E$5:$E$80) -> 0 | H13: =SUMIF('07数值索引'!$A$5:$A$80,$A13,'07数值索引'!$F$5:$F$80) -> 1 | I13: =SUMIF('07数值索引'!$A$5:$A$80,$A13,'07数值索引'!$G$5:$G$80) -> 0 | J13: =SUMIF('07数值索引'!$A$5:$A$80,$A13,'07数值索引'!$H$5:$H$80) -> 0 | K13: =SUMIF('07数值索引'!$A$5:$A$80,$A13,'07数值索引'!$I$5:$I$80) -> 0 | L13: =SUMIF('07数值索引'!$A$5:$A$80,$A13,'07数值索引'!$J$5:$J$80) -> 0 | M13: =SUMIF('07数值索引'!$A$5:$A$80,$A13,'07数值索引'!$M$5:$M$80) -> 0
A14: K-SLV-REL | B14: 三千两银票 | C14: 用于赈济灾民 | D14: 无 | E14: 救助人数更多，但公开行动增加追捕 | F14: =SUMIF('07数值索引'!$A$5:$A$80,$A14,'07数值索引'!$D$5:$D$80) -> 2 | G14: =SUMIF('07数值索引'!$A$5:$A$80,$A14,'07数值索引'!$E$5:$E$80) -> 0 | H14: =SUMIF('07数值索引'!$A$5:$A$80,$A14,'07数值索引'!$F$5:$F$80) -> 0 | I14: =SUMIF('07数值索引'!$A$5:$A$80,$A14,'07数值索引'!$G$5:$G$80) -> 1 | J14: =SUMIF('07数值索引'!$A$5:$A$80,$A14,'07数值索引'!$H$5:$H$80) -> 0 | K14: =SUMIF('07数值索引'!$A$5:$A$80,$A14,'07数值索引'!$I$5:$I$80) -> 0 | L14: =SUMIF('07数值索引'!$A$5:$A$80,$A14,'07数值索引'!$J$5:$J$80) -> 0 | M14: =SUMIF('07数值索引'!$A$5:$A$80,$A14,'07数值索引'!$M$5:$M$80) -> 0
A15: K-SLV-TAKE | B15: 三千两银票 | C15: 带走 | D15: 无 | E15: 把赃款重新解释成活命盘缠 | F15: =SUMIF('07数值索引'!$A$5:$A$80,$A15,'07数值索引'!$D$5:$D$80) -> -2 | G15: =SUMIF('07数值索引'!$A$5:$A$80,$A15,'07数值索引'!$E$5:$E$80) -> 0 | H15: =SUMIF('07数值索引'!$A$5:$A$80,$A15,'07数值索引'!$F$5:$F$80) -> -2 | I15: =SUMIF('07数值索引'!$A$5:$A$80,$A15,'07数值索引'!$G$5:$G$80) -> 0 | J15: =SUMIF('07数值索引'!$A$5:$A$80,$A15,'07数值索引'!$H$5:$H$80) -> 0 | K15: =SUMIF('07数值索引'!$A$5:$A$80,$A15,'07数值索引'!$I$5:$I$80) -> 0 | L15: =SUMIF('07数值索引'!$A$5:$A$80,$A15,'07数值索引'!$J$5:$J$80) -> 1 | M15: =SUMIF('07数值索引'!$A$5:$A$80,$A15,'07数值索引'!$M$5:$M$80) -> 0
A16: K-SEAL-DEST | B16: 圣女旧印 | C16: 交给阿禾毁掉 | D16: 阿禾仍在场 | E16: 主动关闭最便利的旧权力入口 | F16: =SUMIF('07数值索引'!$A$5:$A$80,$A16,'07数值索引'!$D$5:$D$80) -> 2 | G16: =SUMIF('07数值索引'!$A$5:$A$80,$A16,'07数值索引'!$E$5:$E$80) -> -1 | H16: =SUMIF('07数值索引'!$A$5:$A$80,$A16,'07数值索引'!$F$5:$F$80) -> 1 | I16: =SUMIF('07数值索引'!$A$5:$A$80,$A16,'07数值索引'!$G$5:$G$80) -> 0 | J16: =SUMIF('07数值索引'!$A$5:$A$80,$A16,'07数值索引'!$H$5:$H$80) -> 0 | K16: =SUMIF('07数值索引'!$A$5:$A$80,$A16,'07数值索引'!$I$5:$I$80) -> 0 | L16: =SUMIF('07数值索引'!$A$5:$A$80,$A16,'07数值索引'!$J$5:$J$80) -> 0 | M16: =SUMIF('07数值索引'!$A$5:$A$80,$A16,'07数值索引'!$M$5:$M$80) -> 0
... A18: K-SEAL-HIDE | B18: 圣女旧印 | C18: 藏起保留 | D18: 无 | E18: 暂时不用，但保留随时返回的可能 | F18: =SUMIF('07数值索引'!$A$5:$A$80,$A18,'07数值索引'!$D$5:$D$80) -> -1 | G18: =SUMIF('07数值索引'!$A$5:$A$80,$A18,'07数值索引'!$E$5:$E$80) -> 1 | H18: =SUMIF('07数值索引'!$A$5:$A$80,$A18,'07数值索引'!$F$5:$F$80) -> 0 | I18: =SUMIF('07数值索引'!$A$5:$A$80,$A18,'07数值索引'!$G$5:$G$80) -> 0 | J18: =SUMIF('07数值索引'!$A$5:$A$80,$A18,'07数值索引'!$H$5:$H$80) -> 0 | K18: =SUMIF('07数值索引'!$A$5:$A$80,$A18,'07数值索引'!$I$5:$I$80) -> 0 | L18: =SUMIF('07数值索引'!$A$5:$A$80,$A18,'07数值索引'!$J$5:$J$80) -> 0 | M18: =SUMIF('07数值索引'!$A$5:$A$80,$A18,'07数值索引'!$M$5:$M$80) -> 0
A20: 终局行动（与物品处置叠加）
A21: 行动ID | B21: 行动 | C21: 性质 | D21: 结果与显示条件 | E21: 承担 | F21: 依赖 | G21: 信任 | H21: 追捕 | I21: 备注
A22: ACT-PROTECT | B22: 让阿禾或接头人带证据先走，自己留下拖延 | C22: 承担行动 | D22: 证据已交付；中信任阿禾路线必被魏先截停 | E22: =SUMIF('07数值索引'!$A$5:$A$80,$A22,'07数值索引'!$D$5:$D$80) -> 2 | F22: =SUMIF('07数值索引'!$A$5:$A$80,$A22,'07数值索引'!$E$5:$E$80) -> 0 | G22: =SUMIF('07数值索引'!$A$5:$A$80,$A22,'07数值索引'!$F$5:$F$80) -> 2 | H22: =SUMIF('07数值索引'!$A$5:$A$80,$A22,'07数值索引'!$G$5:$G$80) -> 3 | I22: 追捕达到阈值时《证人之死》
A23: ACT-UNDER | B23: 经验证暗号后从旧地道撤离 | C23: 结构性行动 | D23: 完整接头线索；或高信任阿禾共享撤离路线 | E23: =SUMIF('07数值索引'!$A$5:$A$80,$A23,'07数值索引'!$D$5:$D$80) -> 1 | F23: =SUMIF('07数值索引'!$A$5:$A$80,$A23,'07数值索引'!$E$5:$E$80) -> 0 | G23: =SUMIF('07数值索引'!$A$5:$A$80,$A23,'07数值索引'!$F$5:$F$80) -> 0 | H23: =SUMIF('07数值索引'!$A$5:$A$80,$A23,'07数值索引'!$G$5:$G$80) -> -1 | I23: 满足承担条件时《继续前行》
A24: ACT-SAINT | B24: 佩印，以神谕宣布魏先背叛神意 | C24: 重新掌权 | D24: 必须已佩戴旧印 | E24: =SUMIF('07数值索引'!$A$5:$A$80,$A24,'07数值索引'!$D$5:$D$80) -> 0 | F24: =SUMIF('07数值索引'!$A$5:$A$80,$A24,'07数值索引'!$E$5:$E$80) -> 3 | G24: =SUMIF('07数值索引'!$A$5:$A$80,$A24,'07数值索引'!$F$5:$F$80) -> 0 | H24: =SUMIF('07数值索引'!$A$5:$A$80,$A24,'07数值索引'!$G$5:$G$80) -> 2 | I24: 依赖高时《第二位圣女》；追捕极高时《最后一次神迹》
A25: ACT-ESCAPE | B25: 携带仍在自己手中的银票或证据独自逃亡 | C25: 逃避 | D25: 未再次牺牲阿禾 | E25: =SUMIF('07数值索引'!$A$5:$A$80,$A25,'07数值索引'!$D$5:$D$80) -> -2 | F25: =SUMIF('07数值索引'!$A$5:$A$80,$A25,'07数值索引'!$E$5:$E$80) -> 0 | G25: =SUMIF('07数值索引'!$A$5:$A$80,$A25,'07数值索引'!$F$5:$F$80) -> -2 | H25: =SUMIF('07数值索引'!$A$5:$A$80,$A25,'07数值索引'!$G$5:$G$80) -> 1 | I25: 对白表现为‘以后还能补救’式自我辩解
A26: ACT-BETRAY | B26: 让阿禾携带空包或假证据引开追兵 | C26: 再次利用 | D26: 仅在弃责状态、低信任、真实证据仍由阿芸控制时显示 | E26: =SUMIF('07数值索引'!$A$5:$A$80,$A26,'07数值索引'!$D$5:$D$80) -> -3 | F26: =SUMIF('07数值索引'!$A$5:$A$80,$A26,'07数值索引'!$E$5:$E$80) -> 0 | G26: =SUMIF('07数值索引'!$A$5:$A$80,$A26,'07数值索引'!$F$5:$F$80) -> -3 | H26: =SUMIF('07数值索引'!$A$5:$A$80,$A26,'07数值索引'!$G$5:$G$80) -> 1 | I26: 触发《审判》；真实账簿已交阿禾时互斥

Sheet 06结局判定
A1: 06｜结局判定顺序与阈值
A2: 先处理过程死亡与再次背叛，再处理身份复归与承担。阿禾信任决定证据是否被接受和撤离权限，不能单独替代最终判定。
A4: 优先级 | B4: 结局 | C4: 精确条件 | D4: 叙事解释 | E4: 判词 | F4: 类型 | G4: 已实现 | H4: 备注
A5: 1 | B5: 《无名尸体》 | C5: 无名失败标记=1 | D5: S03身份确认前的直接失败 | E5: 她直到最后，也不知道别人为什么恨她。 | F5: 过程死亡 | G5: 是 | H5: 不进入后半段
A6: 2 | B6: 《证人之死》 | C6: 保护行动=1；且中信任截停或追捕压力≥6 | D6: 阿芸留下确保阿禾／接头人与证据离开 | E6: 她无法用死亡偿清旧债，但证据越过了她的尸体。 | F6: 过程死亡 | G6: 是 | H6: 优先于继续前行
A7: 3 | B7: 《最后一次神迹》 | C7: 圣女行动=1；追捕压力≥8 | D7: 聚众失控，死亡再次被包装为殉道 | E7: 她终于说出了真话。可锣鼓太响，没有人听见。 | F7: 过程死亡 | G7: 是 | H7: 优先于第二位圣女
A8: 4 | B8: 《审判》 | C8: 逃跑行动=1；信任≤-3；弃责状态=是；私藏证据≥2；带走银票=1；再次背叛=1 | D8: 阿芸已放弃赎罪，并再次把阿禾作为错误目标 | E8: 她曾经让别人替自己去死。这一次，阿禾没有再替她走。 | F8: 关系结局 | G8: 是 | H8: 真实账簿已交阿禾时不可触发
A9: 5 | B9: 《第二位圣女》 | C9: 圣女行动=1；依赖≥5；重新佩印=1；追捕<8 | D9: 救人或公开真相，却重新控制信众与解释权 | E9: 第一位圣女死在河里。第二位圣女从她的尸体里站了起来。 | F9: 身份结局 | G9: 是 | H9: 交出部分证据也不能自动避免
A10: 6 | B10: 《继续前行》 | C10: 承担≥7；证据送出≥1；未带走银票；依赖≤4；且高信任协作或地道行动成立 | D10: 没有宽恕与领袖奖励，只开始承担 | E10: 她没有洗清自己的名字。她只是终于不再擦掉别人的名字。 | F10: 承担结局 | G10: 是 | H10: 高信任同行版／接头人独行版
A11: 7 | B11: 《逃避》 | C11: 以上均未命中；通常为自行保留、携款或ACT-ESCAPE | D11: 做过局部正确选择，仍用‘以后补救’回避当下责任 | E11: 无知曾经替她遮住脸。现在，她只能自己蒙上眼睛。 | F11: 兜底结局 | G11: 是 | H11: 与《审判》的区别是没有主动牺牲阿禾
A13: 问题 | B13: 回答
A14: 为什么高信任不是自动OE？ | B14: 高信任只解锁协作撤离；仍需交出证据、拒绝携款与旧印，并达到承担阈值。
A15: 为什么中信任会遭遇魏先？ | B15: 魏先始终在追捕；中信任时阿禾只带证据离开、不共享撤离路线，阿芸被留在原地截住。
A16: 为什么逃避需要精细对白？ | B16: 她应以‘活着才能以后补救’自我辩解，而不是突然宣告自己不想赎罪。
A17: 为什么审判需要弃责前情？ | B17: 只有在私藏证据、携款、低承担并主动再次利用阿禾时才显示背叛选项。

Sheet 07数值索引
A1: 07｜数值与判定标记索引（唯一数据源）
A2: 黄色列可修改。其他工作表通过公式读取本表；修改后请到08可达路径测试确认所有结局仍可到达。
A4: 事件ID | B4: 场次 | C4: 类型 | D4: 承担 | E4: 依赖 | F4: 信任 | G4: 追捕 | H4: 证据送出 | I4: 证据私藏 | J4: 带走银票 | K4: 重新佩印 | L4: 再次背叛 | M4: 接头线索 | N4: 保护行动 | O4: 地道行动 | P4: 圣女行动 | Q4: 逃跑行动 | R4: 无名失败 | S4: 说明
A5: SYS-START | B5: 系统 | C5: 初始值 | D5: 0 | E5: 0 | F5: 1 | G5: 1 | H5: 0 | I5: 0 | J5: 0 | K5: 0 | L5: 0 | M5: 0 | N5: 0 | O5: 0 | P5: 0 | Q5: 0 | R5: 0 | S5: 阿禾因救人而保留最低限度善意；追兵已在沿河搜索
A6: SYS-WEI | B6: S04→S05 | C6: 固定推进 | D6: 0 | E6: 0 | F6: 0 | G6: 1 | H6: 0 | I6: 0 | J6: 0 | K6: 0 | L6: 0 | M6: 0 | N6: 0 | O6: 0 | P6: 0 | Q6: 0 | R6: 0 | S6: 魏先进入县城，所有路线固定增加一次追捕压力
A7: S01-O01 | B7: S01 | C7: 对话 | D7: 0 | E7: 0 | F7: 1 | G7: 0 | H7: 0 | I7: 0 | J7: 0 | K7: 0 | L7: 0 | M7: 0 | N7: 0 | O7: 0 | P7: 0 | Q7: 0 | R7: 0 | S7: 坦白不知道来历，也不想连累阿禾
A8: S01-O02 | B8: S01 | C8: 对话 | D8: 0 | E8: 0 | F8: -1 | G8: 0 | H8: 0 | I8: 0 | J8: 0 | K8: 0 | L8: 0 | M8: 0 | N8: 0 | O8: 0 | P8: 0 | Q8: 0 | R8: 0 | S8: 否认追兵存在；阿禾暗中观察
A9: S01-O03 | B9: S01 | C9: 对话 | D9: 0 | E9: 0 | F9: 0 | G9: 0 | H9: 0 | I9: 0 | J9: 0 | K9: 0 | L9: 0 | M9: 0 | N9: 0 | O9: 0 | P9: 0 | Q9: 0 | R9: 0 | S9: 试探阿禾会不会交人
A10: S02-O01 | B10: S02 | C10: 身份态度 | D10: 0 | E10: 0 | F10: 1 | G10: 0 | H10: 0 | I10: 0 | J10: 0 | K10: 0 | L10: 0 | M10: 0 | N10: 0 | O10: 0 | P10: 0 | Q10: 0 | R10: 0 | S10: 要求沈婆起身并否认身份
A11: S02-O02 | B11: S02 | C11: 身份态度 | D11: 0 | E11: 0 | F11: 0 | G11: 0 | H11: 0 | I11: 0 | J11: 0 | K11: 0 | L11: 0 | M11: 0 | N11: 0 | O11: 0 | P11: 0 | Q11: 0 | R11: 0 | S11: 追问旧法会，保留判断
A12: S02-O03 | B12: S02 | C12: 身份态度 | D12: 0 | E12: 1 | F12: -1 | G12: 1 | H12: 0 | I12: 0 | J12: 0 | K12: 0 | L12: 0 | M12: 0 | N12: 0 | O12: 0 | P12: 0 | Q12: 0 | R12: 0 | S12: 默认跪拜换取帮助；消息开始外泄
A13: C-S03-A-F-R | B13: S03 | C13: 关键 | D13: 1 | E13: 0 | F13: 1 | G13: 0 | H13: 0 | I13: 0 | J13: 0 | K13: 0 | L13: 0 | M13: 0 | N13: 0 | O13: 0 | P13: 0 | Q13: 0 | R13: 0 | S13: 两人先救伤者和孩子；骚乱暂缓，但无法解决整体饥荒
A14: C-S03-A-I-R | B14: S03 | C14: 关键 | D14: 1 | E14: 0 | F14: 1 | G14: 1 | H14: 0 | I14: 0 | J14: 0 | K14: 0 | L14: 0 | M14: 1 | N14: 0 | O14: 0 | P14: 0 | Q14: 0 | R14: 0 | S14: 阿禾带人找到后院藏粮，粮商记住她的脸
A15: C-S03-A-P-R | B15: S03 | C15: 冲突 | D15: 0 | E15: 0 | F15: 0 | G15: 0 | H15: 0 | I15: 0 | J15: 0 | K15: 0 | L15: 0 | M15: 0 | N15: 0 | O15: 0 | P15: 0 | Q15: 0 | R15: 0 | S15: 阿禾把画像推回去：‘纸上的人又不会搬粮。’
A16: C-S03-A-F-P | B16: S03 | C16: 普通 | D16: 1 | E16: 1 | F16: 0 | G16: 1 | H16: 0 | I16: 0 | J16: 0 | K16: 0 | L16: 0 | M16: 0 | N16: 0 | O16: 0 | P16: 0 | Q16: 0 | R16: 0 | S16: 阿芸以训练过的声音维持秩序，阿禾分粮；救助变快，但阿禾开始警惕
... A59: SYS-WEI-MID | B59: S05 | C59: 固定推进 | D59: 0 | E59: 0 | F59: 0 | G59: 2 | H59: 0 | I59: 0 | J59: 0 | K59: 0 | L59: 0 | M59: 0 | N59: 0 | O59: 0 | P59: 0 | Q59: 0 | R59: 0 | S59: 阿禾中信任时只带证据离开，不共享撤离路线；魏先在阿芸离开前截住她

Sheet 08可达路径测试
A1: 08｜结局可达路径与合法性自动测试
A2: 总测试=结局匹配＋事件ID完整＋逐步前置合法。修改07数值索引后，需同时确认AF、AI、AJ和AK列。
A4: 路线ID | B4: 路线名称 | C4: 步骤1 | D4: 步骤2 | E4: 步骤3 | F4: 步骤4 | G4: 步骤5 | H4: 步骤6 | I4: 步骤7 | J4: 步骤8 | K4: 步骤9 | L4: 步骤10 | M4: 步骤11 | N4: 步骤12 | O4: 承担 | P4: 依赖 | Q4: 信任 | R4: 追捕 | S4: 证据送出 | T4: 证据私藏 | U4: 带走银票 | V4: 重新佩印 | W4: 再次背叛 | X4: 接头线索 | Y4: 保护 | Z4: 地道 | AA4: 圣女 | AB4: 逃跑 | AC4: 无名失败 | AD4: 实际结局 | AE4: 预期结局 | AF4: 结局测试 | AG4: 设计说明 | AH4: 弃责状态 | AI4: ID完整性 | AJ4: 前置合法性 | AK4: 总测试
A5: R01 | B5: 继续前行—阿禾高信任同行 | C5: SYS-START | D5: S01-O01 | E5: S02-O01 | F5: C-S03-A-F-R | G5: S04-A04 | H5: S04-B01 | I5: K-LDG-AHE | J5: K-LTR-AHE | K5: K-SLV-VIC | L5: K-SEAL-DEST | M5: SYS-WEI | N5: ACT-PROTECT | O5: =0+SUMIF('07数值索引'!$A$5:$A$80,C5,'07数值索引'!$D$5:$D$80)+SUMIF('07数值索引'!$A$5:$A$80,D5,'07数值索引'!$D$5:$D$80)+SUMIF('07数值索引'!$A$5:$A$80,E5,'07数值索引'!$D$5:$D$80)+SUMIF('07数值索引'!$A$5:$A$80,F5,'07数值索引'!$D$5:$D$80)+SUMIF('07数值索引'!$A$5:$A$80,G5,'07数值索引'!$D$5:$D$80)+SUMIF('07数值索引'!$A$5:$A$80,H5,'07数值索引'!$D$5:$D$80)+SUMIF('07数值索引'!$A$5:$A$80,I5,'07数值索引'!$D$5:$D$80)+SUMIF('07数值索引'!$A$5:$A$80,J5,'07数值索引'!$D$5:$D$80)+SUMIF('07数值索引'!$A$5:$A$80,K5,'07数值索引'!$D$5:$D$80)+SUMIF('07数值索引'!$A$5:$A$80,L5,'07数值索引'!$D$5:$D$80)+SUMIF('07数值索引'!$A$5:$A$80,M5,'07数值索引'!$D$5:$D$80)+SUMIF('07数值索引'!$A$5:$A$80,N5,'07数值索引'!$D$5:$D$80) -> 16 | P5: =0+SUMIF('07数值索引'!$A$5:$A$80,C5,'07数值索引'!$E$5:$E$80)+SUMIF('07数值索引'!$A$5:$A$80,D5,'07数值索引'!$E$5:$E$80)+SUMIF('07数值索引'!$A$5:$A$80,E5,'07数值索引'!$E$5:$E$80)+SUMIF('07数值索引'!$A$5:$A$80,F5,'07数值索引'!$E$5:$E$80)+SUMIF('07数值索引'!$A$5:$A$80,G5,'07数值索引'!$E$5:$E$80)+SUMIF('07数值索引'!$A$5:$A$80,H5,'07数值索引'!$E$5:$E$80)+SUMIF('07数值索引'!$A$5:$A$80,I5,'07数值索引'!$E$5:$E$80)+SUMIF('07数值索引'!$A$5:$A$80,J5,'07数值索引'!$E$5:$E$80)+SUMIF('07数值索引'!$A$5:$A$80,K5,'07数值索引'!$E$5:$E$80)+SUMIF('07数值索引'!$A$5:$A$80,L5,'07数值索引'!$E$5:$E$80)+SUMIF('07数值索引'!$A$5:$A$80,M5,'07数值索引'!$E$5:$E$80)+SUMIF('07数值索引'!$A$5:$A$80,N5,'07数值索引'!$E$5:$E$80) -> -1 | Q5: =0+SUMIF('07数值索引'!$A$5:$A$80,C5,'07数值索引'!$F$5:$F$80)+SUMIF('07数值索引'!$A$5:$A$80,D5,'07数值索引'!$F$5:$F$80)+SUMIF('07数值索引'!$A$5:$A$80,E5,'07数值索引'!$F$5:$F$80)+SUMIF('07数值索引'!$A$5:$A$80,F5,'07数值索引'!$F$5:$F$80)+SUMIF('07数值索引'!$A$5:$A$80,G5,'07数值索引'!$F$5:$F$80)+SUMIF('07数值索引'!$A$5:$A$80,H5,'07数值索引'!$F$5:$F$80)+SUMIF('07数值索引'!$A$5:$A$80,I5,'07数值索引'!$F$5:$F$80)+SUMIF('07数值索引'!$A$5:$A$80,J5,'07数值索引'!$F$5:$F$80)+SUMIF('07数值索引'!$A$5:$A$80,K5,'07数值索引'!$F$5:$F$80)+SUMIF('07数值索引'!$A$5:$A$80,L5,'07数值索引'!$F$5:$F$80)+SUMIF('07数值索引'!$A$5:$A$80,M5,'07数值索引'!$F$5:$F$80)+SUMIF('07数值索引'!$A$5:$A$80,N5,'07数值索引'!$F$5:$F$80) -> 12 | R5: =0+SUMIF('07数值索引'!$A$5:$A$80,C5,'07数值索引'!$G$5:$G$80)+SUMIF('07数值索引'!$A$5:$A$80,D5,'07数值索引'!$G$5:$G$80)+SUMIF('07数值索引'!$A$5:$A$80,E5,'07数值索引'!$G$5:$G$80)+SUMIF('07数值索引'!$A$5:$A$80,F5,'07数值索引'!$G$5:$G$80)+SUMIF('07数值索引'!$A$5:$A$80,G5,'07数值索引'!$G$5:$G$80)+SUMIF('07数值索引'!$A$5:$A$80,H5,'07数值索引'!$G$5:$G$80)+SUMIF('07数值索引'!$A$5:$A$80,I5,'07数值索引'!$G$5:$G$80)+SUMIF('07数值索引'!$A$5:$A$80,J5,'07数值索引'!$G$5:$G$80)+SUMIF('07数值索引'!$A$5:$A$80,K5,'07数值索引'!$G$5:$G$80)+SUMIF('07数值索引'!$A$5:$A$80,L5,'07数值索引'!$G$5:$G$80)+SUMIF('07数值索引'!$A$5:$A$80,M5,'07数值索引'!$G$5:$G$80)+SUMIF('07数值索引'!$A$5:$A$80,N5,'07数值索引'!$G$5:$G$80) -> 5 | S5: =0+SUMIF('07数值索引'!$A$5:$A$80,C5,'07数值索引'!$H$5:$H$80)+SUMIF('07数值索引'!$A$5:$A$80,D5,'07数值索引'!$H$5:$H$80)+SUMIF('07数值索引'!$A$5:$A$80,E5,'07数值索引'!$H$5:$H$80)+SUMIF('07数值索引'!$A$5:$A$80,F5,'07数值索引'!$H$5:$H$80)+SUMIF('07数值索引'!$A$5:$A$80,G5,'07数值索引'!$H$5:$H$80)+SUMIF('07数值索引'!$A$5:$A$80,H5,'07数值索引'!$H$5:$H$80)+SUMIF('07数值索引'!$A$5:$A$80,I5,'07数值索引'!$H$5:$H$80)+SUMIF('07数值索引'!$A$5:$A$80,J5,'07数值索引'!$H$5:$H$80)+SUMIF('07数值索引'!$A$5:$A$80,K5,'07数值索引'!$H$5:$H$80)+SUMIF('07数值索引'!$A$5:$A$80,L5,'07数值索引'!$H$5:$H$80)+SUMIF('07数值索引'!$A$5:$A$80,M5,'07数值索引'!$H$5:$H$80)+SUMIF('07数值索引'!$A$5:$A$80,N5,'07数值索引'!$H$5:$H$80) -> 2 | T5: =0+SUMIF('07数值索引'!$A$5:$A$80,C5,'07数值索引'!$I$5:$I$80)+SUMIF('07数值索引'!$A$5:$A$80,D5,'07数值索引'!$I$5:$I$80)+SUMIF('07数值索引'!$A$5:$A$80,E5,'07数值索引'!$I$5:$I$80)+SUMIF('07数值索引'!$A$5:$A$80,F5,'07数值索引'!$I$5:$I$80)+SUMIF('07数值索引'!$A$5:$A$80,G5,'07数值索引'!$I$5:$I$80)+SUMIF('07数值索引'!$A$5:$A$80,H5,'07数值索引'!$I$5:$I$80)+SUMIF('07数值索引'!$A$5:$A$80,I5,'07数值索引'!$I$5:$I$80)+SUMIF('07数值索引'!$A$5:$A$80,J5,'07数值索引'!$I$5:$I$80)+SUMIF('07数值索引'!$A$5:$A$80,K5,'07数值索引'!$I$5:$I$80)+SUMIF('07数值索引'!$A$5:$A$80,L5,'07数值索引'!$I$5:$I$80)+SUMIF('07数值索引'!$A$5:$A$80,M5,'07数值索引'!$I$5:$I$80)+SUMIF('07数值索引'!$A$5:$A$80,N5,'07数值索引'!$I$5:$I$80) -> 0 | U5: =0+SUMIF('07数值索引'!$A$5:$A$80,C5,'07数值索引'!$J$5:$J$80)+SUMIF('07数值索引'!$A$5:$A$80,D5,'07数值索引'!$J$5:$J$80)+SUMIF('07数值索引'!$A$5:$A$80,E5,'07数值索引'!$J$5:$J$80)+SUMIF('07数值索引'!$A$5:$A$80,F5,'07数值索引'!$J$5:$J$80)+SUMIF('07数值索引'!$A$5:$A$80,G5,'07数值索引'!$J$5:$J$80)+SUMIF('07数值索引'!$A$5:$A$80,H5,'07数值索引'!$J$5:$J$80)+SUMIF('07数值索引'!$A$5:$A$80,I5,'07数值索引'!$J$5:$J$80)+SUMIF('07数值索引'!$A$5:$A$80,J5,'07数值索引'!$J$5:$J$80)+SUMIF('07数值索引'!$A$5:$A$80,K5,'07数值索引'!$J$5:$J$80)+SUMIF('07数值索引'!$A$5:$A$80,L5,'07数值索引'!$J$5:$J$80)+SUMIF('07数值索引'!$A$5:$A$80,M5,'07数值索引'!$J$5:$J$80)+SUMIF('07数值索引'!$A$5:$A$80,N5,'07数值索引'!$J$5:$J$80) -> 0 | V5: =0+SUMIF('07数值索引'!$A$5:$A$80,C5,'07数值索引'!$K$5:$K$80)+SUMIF('07数值索引'!$A$5:$A$80,D5,'07数值索引'!$K$5:$K$80)+SUMIF('07数值索引'!$A$5:$A$80,E5,'07数值索引'!$K$5:$K$80)+SUMIF('07数值索引'!$A$5:$A$80,F5,'07数值索引'!$K$5:$K$80)+SUMIF('07数值索引'!$A$5:$A$80,G5,'07数值索引'!$K$5:$K$80)+SUMIF('07数值索引'!$A$5:$A$80,H5,'07数值索引'!$K$5:$K$80)+SUMIF('07数值索引'!$A$5:$A$80,I5,'07数值索引'!$K$5:$K$80)+SUMIF('07数值索引'!$A$5:$A$80,J5,'07数值索引'!$K$5:$K$80)+SUMIF('07数值索引'!$A$5:$A$80,K5,'07数值索引'!$K$5:$K$80)+SUMIF('07数值索引'!$A$5:$A$80,L5,'07数值索引'!$K$5:$K$80)+SUMIF('07数值索引'!$A$5:$A$80,M5,'07数值索引'!$K$5:$K$80)+SUMIF('07数值索引'!$A$5:$A$80,N5,'07数值索引'!$K$5:$K$80) -> 0 | W5: =0+SUMIF('07数值索引'!$A$5:$A$80,C5,'07数值索引'!$L$5:$L$80)+SUMIF('07数值索引'!$A$5:$A$80,D5,'07数值索引'!$L$5:$L$80)+SUMIF('07数值索引'!$A$5:$A$80,E5,'07数值索引'!$L$5:$L$80)+SUMIF('07数值索引'!$A$5:$A$80,F5,'07数值索引'!$L$5:$L$80)+SUMIF('07数值索引'!$A$5:$A$80,G5,'07数值索引'!$L$5:$L$80)+SUMIF('07数值索引'!$A$5:$A$80,H5,'07数值索引'!$L$5:$L$80)+SUMIF('07数值索引'!$A$5:$A$80,I5,'07数值索引'!$L$5:$L$80)+SUMIF('07数值索引'!$A$5:$A$80,J5,'07数值索引'!$L$5:$L$80)+SUMIF('07数值索引'!$A$5:$A$80,K5,'07数值索引'!$L$5:$L$80)+SUMIF('07数值索引'!$A$5:$A$80,L5,'07数值索引'!$L$5:$L$80)+SUMIF('07数值索引'!$A$5:$A$80,M5,'07数值索引'!$L$5:$L$80)+SUMIF('07数值索引'!$A$5:$A$80,N5,'07数值索引'!$L$5:$L$80) -> 0 | X5: =0+SUMIF('07数值索引'!$A$5:$A$80,C5,'07数值索引'!$M$5:$M$80)+SUMIF('07数值索引'!$A$5:$A$80,D5,'07数值索引'!$M$5:$M$80)+SUMIF('07数值索引'!$A$5:$A$80,E5,'07数值索引'!$M$5:$M$80)+SUMIF('07数值索引'!$A$5:$A$80,F5,'07数值索引'!$M$5:$M$80)+SUMIF('07数值索引'!$A$5:$A$80,G5,'07数值索引'!$M$5:$M$80)+SUMIF('07数值索引'!$A$5:$A$80,H5,'07数值索引'!$M$5:$M$80)+SUMIF('07数值索引'!$A$5:$A$80,I5,'07数值索引'!$M$5:$M$80)+SUMIF('07数值索引'!$A$5:$A$80,J5,'07数值索引'!$M$5:$M$80)+SUMIF('07数值索引'!$A$5:$A$80,K5,'07数值索引'!$M$5:$M$80)+SUMIF('07数值索引'!$A$5:$A$80,L5,'07数值索引'!$M$5:$M$80)+SUMIF('07数值索引'!$A$5:$A$80,M5,'07数值索引'!$M$5:$M$80)+SUMIF('07数值索引'!$A$5:$A$80,N5,'07数值索引'!$M$5:$M$80) -> 0 | Y5: =0+SUMIF('07数值索引'!$A$5:$A$80,C5,'07数值索引'!$N$5:$N$80)+SUMIF('07数值索引'!$A$5:$A$80,D5,'07数值索引'!$N$5:$N$80)+SUMIF('07数值索引'!$A$5:$A$80,E5,'07数值索引'!$N$5:$N$80)+SUMIF('07数值索引'!$A$5:$A$80,F5,'07数值索引'!$N$5:$N$80)+SUMIF('07数值索引'!$A$5:$A$80,G5,'07数值索引'!$N$5:$N$80)+SUMIF('07数值索引'!$A$5:$A$80,H5,'07数值索引'!$N$5:$N$80)+SUMIF('07数值索引'!$A$5:$A$80,I5,'07数值索引'!$N$5:$N$80)+SUMIF('07数值索引'!$A$5:$A$80,J5,'07数值索引'!$N$5:$N$80)+SUMIF('07数值索引'!$A$5:$A$80,K5,'07数值索引'!$N$5:$N$80)+SUMIF('07数值索引'!$A$5:$A$80,L5,'07数值索引'!$N$5:$N$80)+SUMIF('07数值索引'!$A$5:$A$80,M5,'07数值索引'!$N$5:$N$80)+SUMIF('07数值索引'!$A$5:$A$80,N5,'07数值索引'!$N$5:$N$80) -> 1 | Z5: =0+SUMIF('07数值索引'!$A$5:$A$80,C5,'07数值索引'!$O$5:$O$80)+SUMIF('07数值索引'!$A$5:$A$80,D5,'07数值索引'!$O$5:$O$80)+SUMIF('07数值索引'!$A$5:$A$80,E5,'07数值索引'!$O$5:$O$80)+SUMIF('07数值索引'!$A$5:$A$80,F5,'07数值索引'!$O$5:$O$80)+SUMIF('07数值索引'!$A$5:$A$80,G5,'07数值索引'!$O$5:$O$80)+SUMIF('07数值索引'!$A$5:$A$80,H5,'07数值索引'!$O$5:$O$80)+SUMIF('07数值索引'!$A$5:$A$80,I5,'07数值索引'!$O$5:$O$80)+SUMIF('07数值索引'!$A$5:$A$80,J5,'07数值索引'!$O$5:$O$80)+SUMIF('07数值索引'!$A$5:$A$80,K5,'07数值索引'!$O$5:$O$80)+SUMIF('07数值索引'!$A$5:$A$80,L5,'07数值索引'!$O$5:$O$80)+SUMIF('07数值索引'!$A$5:$A$80,M5,'07数值索引'!$O$5:$O$80)+SUMIF('07数值索引'!$A$5:$A$80,N5,'07数值索引'!$O$5:$O$80) -> 0 | AA5: =0+SUMIF('07数值索引'!$A$5:$A$80,C5,'07数值索引'!$P$5:$P$80)+SUMIF('07数值索引'!$A$5:$A$80,D5,'07数值索引'!$P$5:$P$80)+SUMIF('07数值索引'!$A$5:$A$80,E5,'07数值索引'!$P$5:$P$80)+SUMIF('07数值索引'!$A$5:$A$80,F5,'07数值索引'!$P$5:$P$80)+SUMIF('07数值索引'!$A$5:$A$80,G5,'07数值索引'!$P$5:$P$80)+SUMIF('07数值索引'!$A$5:$A$80,H5,'07数值索引'!$P$5:$P$80)+SUMIF('07数值索引'!$A$5:$A$80,I5,'07数值索引'!$P$5:$P$80)+SUMIF('07数值索引'!$A$5:$A$80,J5,'07数值索引'!$P$5:$P$80)+SUMIF('07数值索引'!$A$5:$A$80,K5,'07数值索引'!$P$5:$P$80)+SUMIF('07数值索引'!$A$5:$A$80,L5,'07数值索引'!$P$5:$P$80)+SUMIF('07数值索引'!$A$5:$A$80,M5,'07数值索引'!$P$5:$P$80)+SUMIF('07数值索引'!$A$5:$A$80,N5,'07数值索引'!$P$5:$P$80) -> 0 | AB5: =0+SUMIF('07数值索引'!$A$5:$A$80,C5,'07数值索引'!$Q$5:$Q$80)+SUMIF('07数值索引'!$A$5:$A$80,D5,'07数值索引'!$Q$5:$Q$80)+SUMIF('07数值索引'!$A$5:$A$80,E5,'07数值索引'!$Q$5:$Q$80)+SUMIF('07数值索引'!$A$5:$A$80,F5,'07数值索引'!$Q$5:$Q$80)+SUMIF('07数值索引'!$A$5:$A$80,G5,'07数值索引'!$Q$5:$Q$80)+SUMIF('07数值索引'!$A$5:$A$80,H5,'07数值索引'!$Q$5:$Q$80)+SUMIF('07数值索引'!$A$5:$A$80,I5,'07数值索引'!$Q$5:$Q$80)+SUMIF('07数值索引'!$A$5:$A$80,J5,'07数值索引'!$Q$5:$Q$80)+SUMIF('07数值索引'!$A$5:$A$80,K5,'07数值索引'!$Q$5:$Q$80)+SUMIF('07数值索引'!$A$5:$A$80,L5,'07数值索引'!$Q$5:$Q$80)+SUMIF('07数值索引'!$A$5:$A$80,M5,'07数值索引'!$Q$5:$Q$80)+SUMIF('07数值索引'!$A$5:$A$80,N5,'07数值索引'!$Q$5:$Q$80) -> 0 | AC5: =0+SUMIF('07数值索引'!$A$5:$A$80,C5,'07数值索引'!$R$5:$R$80)+SUMIF('07数值索引'!$A$5:$A$80,D5,'07数值索引'!$R$5:$R$80)+SUMIF('07数值索引'!$A$5:$A$80,E5,'07数值索引'!$R$5:$R$80)+SUMIF('07数值索引'!$A$5:$A$80,F5,'07数值索引'!$R$5:$R$80)+SUMIF('07数值索引'!$A$5:$A$80,G5,'07数值索引'!$R$5:$R$80)+SUMIF('07数值索引'!$A$5:$A$80,H5,'07数值索引'!$R$5:$R$80)+SUMIF('07数值索引'!$A$5:$A$80,I5,'07数值索引'!$R$5:$R$80)+SUMIF('07数值索引'!$A$5:$A$80,J5,'07数值索引'!$R$5:$R$80)+SUMIF('07数值索引'!$A$5:$A$80,K5,'07数值索引'!$R$5:$R$80)+SUMIF('07数值索引'!$A$5:$A$80,L5,'07数值索引'!$R$5:$R$80)+SUMIF('07数值索引'!$A$5:$A$80,M5,'07数值索引'!$R$5:$R$80)+SUMIF('07数值索引'!$A$5:$A$80,N5,'07数值索引'!$R$5:$R$80) -> 0 | AD5: =IF(AC5>0,"《无名尸体》",IF(AND(Y5>0,R5>=6),"《证人之死》",IF(AND(AA5>0,R5>=8),"《最后一次神迹》",IF(AND(AB5>0,Q5<=-3,T5>=2,U5>0,W5>0,AH5="是"),"《审判》",IF(AND(AA5>0,P5>=5,V5>0),"《第二位圣女》",IF(AND(O5>=7,S5>=1,U5=0,P5<=4,OR(Q5>=4,Z5>0)),"《继续前行》","《逃避》")))))) -> 《继续前行》 | AE5: 《继续前行》 | AF5: =IF(AD5=AE5,"PASS","CHECK") -> PASS | AG5: 高信任解锁协作；低暴露使保护行动不致死 | AH5: =IF(AND(O5<=0,T5>=2,U5=1),"是","否") -> 否 | AI5: =IF(AND(OR(C5="",COUNTIF('07数值索引'!$A$5:$A$80,C5)=1),OR(D5="",COUNTIF('07数值索引'!$A$5:$A$80,D5)=1),OR(E5="",COUNTIF('07数值索引'!$A$5:$A$80,E5)=1),OR(F5="",COUNTIF('07数值索引'!$A$5:$A$80,F5)=1),OR(G5="",COUNTIF('07数值索引'!$A$5:$A$80,G5)=1),OR(H5="",COUNTIF('07数值索引'!$A$5:$A$80,H5)=1),OR(I5="",COUNTIF('07数值索引'!$A$5:$A$80,I5)=1),OR(J5="",COUNTIF('07数值索引'!$A$5:$A$80,J5)=1),OR(K5="",COUNTIF('07数值索引'!$A$5:$A$80,K5)=1),OR(L5="",COUNTIF('07数值索引'!$A$5:$A$80,L5)=1),OR(M5="",COUNTIF('07数值索引'!$A$5:$A$80,M5)=1),OR(N5="",COUNTIF('07数值索引'!$A$5:$A$80,N5)=1)),"PASS","CHECK") -> PASS | AJ5: =IFERROR(VLOOKUP(A5,'08A前置合法性'!$X$5:$Z$20,3,FALSE),"CHECK") -> PASS | AK5: =IF(AND(AF5="PASS",AI5="PASS",AJ5="PASS"),"PASS","CHECK") -> PASS
A6: R02 | B6: 继续前行—接头人独行 | C6: SYS-START | D6: S01-O03 | E6: S02-O02 | F6: C-S03-O-I-R | G6: S04-A03 | H6: S04-B01 | I6: K-LDG-REB | J6: K-LTR-REB | K6: K-SLV-REL | L6: K-SEAL-DEST | M6: SYS-WEI | N6: ACT-UNDER | O6: =0+SUMIF('07数值索引'!$A$5:$A$80,C6,'07数值索引'!$D$5:$D$80)+SUMIF('07数值索引'!$A$5:$A$80,D6,'07数值索引'!$D$5:$D$80)+SUMIF('07数值索引'!$A$5:$A$80,E6,'07数值索引'!$D$5:$D$80)+SUMIF('07数值索引'!$A$5:$A$80,F6,'07数值索引'!$D$5:$D$80)+SUMIF('07数值索引'!$A$5:$A$80,G6,'07数值索引'!$D$5:$D$80)+SUMIF('07数值索引'!$A$5:$A$80,H6,'07数值索引'!$D$5:$D$80)+SUMIF('07数值索引'!$A$5:$A$80,I6,'07数值索引'!$D$5:$D$80)+SUMIF('07数值索引'!$A$5:$A$80,J6,'07数值索引'!$D$5:$D$80)+SUMIF('07数值索引'!$A$5:$A$80,K6,'07数值索引'!$D$5:$D$80)+SUMIF('07数值索引'!$A$5:$A$80,L6,'07数值索引'!$D$5:$D$80)+SUMIF('07数值索引'!$A$5:$A$80,M6,'07数值索引'!$D$5:$D$80)+SUMIF('07数值索引'!$A$5:$A$80,N6,'07数值索引'!$D$5:$D$80) -> 14 | P6: =0+SUMIF('07数值索引'!$A$5:$A$80,C6,'07数值索引'!$E$5:$E$80)+SUMIF('07数值索引'!$A$5:$A$80,D6,'07数值索引'!$E$5:$E$80)+SUMIF('07数值索引'!$A$5:$A$80,E6,'07数值索引'!$E$5:$E$80)+SUMIF('07数值索引'!$A$5:$A$80,F6,'07数值索引'!$E$5:$E$80)+SUMIF('07数值索引'!$A$5:$A$80,G6,'07数值索引'!$E$5:$E$80)+SUMIF('07数值索引'!$A$5:$A$80,H6,'07数值索引'!$E$5:$E$80)+SUMIF('07数值索引'!$A$5:$A$80,I6,'07数值索引'!$E$5:$E$80)+SUMIF('07数值索引'!$A$5:$A$80,J6,'07数值索引'!$E$5:$E$80)+SUMIF('07数值索引'!$A$5:$A$80,K6,'07数值索引'!$E$5:$E$80)+SUMIF('07数值索引'!$A$5:$A$80,L6,'07数值索引'!$E$5:$E$80)+SUMIF('07数值索引'!$A$5:$A$80,M6,'07数值索引'!$E$5:$E$80)+SUMIF('07数值索引'!$A$5:$A$80,N6,'07数值索引'!$E$5:$E$80) -> -1 | Q6: =0+SUMIF('07数值索引'!$A$5:$A$80,C6,'07数值索引'!$F$5:$F$80)+SUMIF('07数值索引'!$A$5:$A$80,D6,'07数值索引'!$F$5:$F$80)+SUMIF('07数值索引'!$A$5:$A$80,E6,'07数值索引'!$F$5:$F$80)+SUMIF('07数值索引'!$A$5:$A$80,F6,'07数值索引'!$F$5:$F$80)+SUMIF('07数值索引'!$A$5:$A$80,G6,'07数值索引'!$F$5:$F$80)+SUMIF('07数值索引'!$A$5:$A$80,H6,'07数值索引'!$F$5:$F$80)+SUMIF('07数值索引'!$A$5:$A$80,I6,'07数值索引'!$F$5:$F$80)+SUMIF('07数值索引'!$A$5:$A$80,J6,'07数值索引'!$F$5:$F$80)+SUMIF('07数值索引'!$A$5:$A$80,K6,'07数值索引'!$F$5:$F$80)+SUMIF('07数值索引'!$A$5:$A$80,L6,'07数值索引'!$F$5:$F$80)+SUMIF('07数值索引'!$A$5:$A$80,M6,'07数值索引'!$F$5:$F$80)+SUMIF('07数值索引'!$A$5:$A$80,N6,'07数值索引'!$F$5:$F$80) -> 4 | R6: =0+SUMIF('07数值索引'!$A$5:$A$80,C6,'07数值索引'!$G$5:$G$80)+SUMIF('07数值索引'!$A$5:$A$80,D6,'07数值索引'!$G$5:$G$80)+SUMIF('07数值索引'!$A$5:$A$80,E6,'07数值索引'!$G$5:$G$80)+SUMIF('07数值索引'!$A$5:$A$80,F6,'07数值索引'!$G$5:$G$80)+SUMIF('07数值索引'!$A$5:$A$80,G6,'07数值索引'!$G$5:$G$80)+SUMIF('07数值索引'!$A$5:$A$80,H6,'07数值索引'!$G$5:$G$80)+SUMIF('07数值索引'!$A$5:$A$80,I6,'07数值索引'!$G$5:$G$80)+SUMIF('07数值索引'!$A$5:$A$80,J6,'07数值索引'!$G$5:$G$80)+SUMIF('07数值索引'!$A$5:$A$80,K6,'07数值索引'!$G$5:$G$80)+SUMIF('07数值索引'!$A$5:$A$80,L6,'07数值索引'!$G$5:$G$80)+SUMIF('07数值索引'!$A$5:$A$80,M6,'07数值索引'!$G$5:$G$80)+SUMIF('07数值索引'!$A$5:$A$80,N6,'07数值索引'!$G$5:$G$80) -> 2 | S6: =0+SUMIF('07数值索引'!$A$5:$A$80,C6,'07数值索引'!$H$5:$H$80)+SUMIF('07数值索引'!$A$5:$A$80,D6,'07数值索引'!$H$5:$H$80)+SUMIF('07数值索引'!$A$5:$A$80,E6,'07数值索引'!$H$5:$H$80)+SUMIF('07数值索引'!$A$5:$A$80,F6,'07数值索引'!$H$5:$H$80)+SUMIF('07数值索引'!$A$5:$A$80,G6,'07数值索引'!$H$5:$H$80)+SUMIF('07数值索引'!$A$5:$A$80,H6,'07数值索引'!$H$5:$H$80)+SUMIF('07数值索引'!$A$5:$A$80,I6,'07数值索引'!$H$5:$H$80)+SUMIF('07数值索引'!$A$5:$A$80,J6,'07数值索引'!$H$5:$H$80)+SUMIF('07数值索引'!$A$5:$A$80,K6,'07数值索引'!$H$5:$H$80)+SUMIF('07数值索引'!$A$5:$A$80,L6,'07数值索引'!$H$5:$H$80)+SUMIF('07数值索引'!$A$5:$A$80,M6,'07数值索引'!$H$5:$H$80)+SUMIF('07数值索引'!$A$5:$A$80,N6,'07数值索引'!$H$5:$H$80) -> 2 | T6: =0+SUMIF('07数值索引'!$A$5:$A$80,C6,'07数值索引'!$I$5:$I$80)+SUMIF('07数值索引'!$A$5:$A$80,D6,'07数值索引'!$I$5:$I$80)+SUMIF('07数值索引'!$A$5:$A$80,E6,'07数值索引'!$I$5:$I$80)+SUMIF('07数值索引'!$A$5:$A$80,F6,'07数值索引'!$I$5:$I$80)+SUMIF('07数值索引'!$A$5:$A$80,G6,'07数值索引'!$I$5:$I$80)+SUMIF('07数值索引'!$A$5:$A$80,H6,'07数值索引'!$I$5:$I$80)+SUMIF('07数值索引'!$A$5:$A$80,I6,'07数值索引'!$I$5:$I$80)+SUMIF('07数值索引'!$A$5:$A$80,J6,'07数值索引'!$I$5:$I$80)+SUMIF('07数值索引'!$A$5:$A$80,K6,'07数值索引'!$I$5:$I$80)+SUMIF('07数值索引'!$A$5:$A$80,L6,'07数值索引'!$I$5:$I$80)+SUMIF('07数值索引'!$A$5:$A$80,M6,'07数值索引'!$I$5:$I$80)+SUMIF('07数值索引'!$A$5:$A$80,N6,'07数值索引'!$I$5:$I$80) -> 0 | U6: =0+SUMIF('07数值索引'!$A$5:$A$80,C6,'07数值索引'!$J$5:$J$80)+SUMIF('07数值索引'!$A$5:$A$80,D6,'07数值索引'!$J$5:$J$80)+SUMIF('07数值索引'!$A$5:$A$80,E6,'07数值索引'!$J$5:$J$80)+SUMIF('07数值索引'!$A$5:$A$80,F6,'07数值索引'!$J$5:$J$80)+SUMIF('07数值索引'!$A$5:$A$80,G6,'07数值索引'!$J$5:$J$80)+SUMIF('07数值索引'!$A$5:$A$80,H6,'07数值索引'!$J$5:$J$80)+SUMIF('07数值索引'!$A$5:$A$80,I6,'07数值索引'!$J$5:$J$80)+SUMIF('07数值索引'!$A$5:$A$80,J6,'07数值索引'!$J$5:$J$80)+SUMIF('07数值索引'!$A$5:$A$80,K6,'07数值索引'!$J$5:$J$80)+SUMIF('07数值索引'!$A$5:$A$80,L6,'07数值索引'!$J$5:$J$80)+SUMIF('07数值索引'!$A$5:$A$80,M6,'07数值索引'!$J$5:$J$80)+SUMIF('07数值索引'!$A$5:$A$80,N6,'07数值索引'!$J$5:$J$80) -> 0 | V6: =0+SUMIF('07数值索引'!$A$5:$A$80,C6,'07数值索引'!$K$5:$K$80)+SUMIF('07数值索引'!$A$5:$A$80,D6,'07数值索引'!$K$5:$K$80)+SUMIF('07数值索引'!$A$5:$A$80,E6,'07数值索引'!$K$5:$K$80)+SUMIF('07数值索引'!$A$5:$A$80,F6,'07数值索引'!$K$5:$K$80)+SUMIF('07数值索引'!$A$5:$A$80,G6,'07数值索引'!$K$5:$K$80)+SUMIF('07数值索引'!$A$5:$A$80,H6,'07数值索引'!$K$5:$K$80)+SUMIF('07数值索引'!$A$5:$A$80,I6,'07数值索引'!$K$5:$K$80)+SUMIF('07数值索引'!$A$5:$A$80,J6,'07数值索引'!$K$5:$K$80)+SUMIF('07数值索引'!$A$5:$A$80,K6,'07数值索引'!$K$5:$K$80)+SUMIF('07数值索引'!$A$5:$A$80,L6,'07数值索引'!$K$5:$K$80)+SUMIF('07数值索引'!$A$5:$A$80,M6,'07数值索引'!$K$5:$K$80)+SUMIF('07数值索引'!$A$5:$A$80,N6,'07数值索引'!$K$5:$K$80) -> 0 | W6: =0+SUMIF('07数值索引'!$A$5:$A$80,C6,'07数值索引'!$L$5:$L$80)+SUMIF('07数值索引'!$A$5:$A$80,D6,'07数值索引'!$L$5:$L$80)+SUMIF('07数值索引'!$A$5:$A$80,E6,'07数值索引'!$L$5:$L$80)+SUMIF('07数值索引'!$A$5:$A$80,F6,'07数值索引'!$L$5:$L$80)+SUMIF('07数值索引'!$A$5:$A$80,G6,'07数值索引'!$L$5:$L$80)+SUMIF('07数值索引'!$A$5:$A$80,H6,'07数值索引'!$L$5:$L$80)+SUMIF('07数值索引'!$A$5:$A$80,I6,'07数值索引'!$L$5:$L$80)+SUMIF('07数值索引'!$A$5:$A$80,J6,'07数值索引'!$L$5:$L$80)+SUMIF('07数值索引'!$A$5:$A$80,K6,'07数值索引'!$L$5:$L$80)+SUMIF('07数值索引'!$A$5:$A$80,L6,'07数值索引'!$L$5:$L$80)+SUMIF('07数值索引'!$A$5:$A$80,M6,'07数值索引'!$L$5:$L$80)+SUMIF('07数值索引'!$A$5:$A$80,N6,'07数值索引'!$L$5:$L$80) -> 0 | X6: =0+SUMIF('07数值索引'!$A$5:$A$80,C6,'07数值索引'!$M$5:$M$80)+SUMIF('07数值索引'!$A$5:$A$80,D6,'07数值索引'!$M$5:$M$80)+SUMIF('07数值索引'!$A$5:$A$80,E6,'07数值索引'!$M$5:$M$80)+SUMIF('07数值索引'!$A$5:$A$80,F6,'07数值索引'!$M$5:$M$80)+SUMIF('07数值索引'!$A$5:$A$80,G6,'07数值索引'!$M$5:$M$80)+SUMIF('07数值索引'!$A$5:$A$80,H6,'07数值索引'!$M$5:$M$80)+SUMIF('07数值索引'!$A$5:$A$80,I6,'07数值索引'!$M$5:$M$80)+SUMIF('07数值索引'!$A$5:$A$80,J6,'07数值索引'!$M$5:$M$80)+SUMIF('07数值索引'!$A$5:$A$80,K6,'07数值索引'!$M$5:$M$80)+SUMIF('07数值索引'!$A$5:$A$80,L6,'07数值索引'!$M$5:$M$80)+SUMIF('07数值索引'!$A$5:$A$80,M6,'07数值索引'!$M$5:$M$80)+SUMIF('07数值索引'!$A$5:$A$80,N6,'07数值索引'!$M$5:$M$80) -> 4 | Y6: =0+SUMIF('07数值索引'!$A$5:$A$80,C6,'07数值索引'!$N$5:$N$80)+SUMIF('07数值索引'!$A$5:$A$80,D6,'07数值索引'!$N$5:$N$80)+SUMIF('07数值索引'!$A$5:$A$80,E6,'07数值索引'!$N$5:$N$80)+SUMIF('07数值索引'!$A$5:$A$80,F6,'07数值索引'!$N$5:$N$80)+SUMIF('07数值索引'!$A$5:$A$80,G6,'07数值索引'!$N$5:$N$80)+SUMIF('07数值索引'!$A$5:$A$80,H6,'07数值索引'!$N$5:$N$80)+SUMIF('07数值索引'!$A$5:$A$80,I6,'07数值索引'!$N$5:$N$80)+SUMIF('07数值索引'!$A$5:$A$80,J6,'07数值索引'!$N$5:$N$80)+SUMIF('07数值索引'!$A$5:$A$80,K6,'07数值索引'!$N$5:$N$80)+SUMIF('07数值索引'!$A$5:$A$80,L6,'07数值索引'!$N$5:$N$80)+SUMIF('07数值索引'!$A$5:$A$80,M6,'07数值索引'!$N$5:$N$80)+SUMIF('07数值索引'!$A$5:$A$80,N6,'07数值索引'!$N$5:$N$80) -> 0 | Z6: =0+SUMIF('07数值索引'!$A$5:$A$80,C6,'07数值索引'!$O$5:$O$80)+SUMIF('07数值索引'!$A$5:$A$80,D6,'07数值索引'!$O$5:$O$80)+SUMIF('07数值索引'!$A$5:$A$80,E6,'07数值索引'!$O$5:$O$80)+SUMIF('07数值索引'!$A$5:$A$80,F6,'07数值索引'!$O$5:$O$80)+SUMIF('07数值索引'!$A$5:$A$80,G6,'07数值索引'!$O$5:$O$80)+SUMIF('07数值索引'!$A$5:$A$80,H6,'07数值索引'!$O$5:$O$80)+SUMIF('07数值索引'!$A$5:$A$80,I6,'07数值索引'!$O$5:$O$80)+SUMIF('07数值索引'!$A$5:$A$80,J6,'07数值索引'!$O$5:$O$80)+SUMIF('07数值索引'!$A$5:$A$80,K6,'07数值索引'!$O$5:$O$80)+SUMIF('07数值索引'!$A$5:$A$80,L6,'07数值索引'!$O$5:$O$80)+SUMIF('07数值索引'!$A$5:$A$80,M6,'07数值索引'!$O$5:$O$80)+SUMIF('07数值索引'!$A$5:$A$80,N6,'07数值索引'!$O$5:$O$80) -> 1 | AA6: =0+SUMIF('07数值索引'!$A$5:$A$80,C6,'07数值索引'!$P$5:$P$80)+SUMIF('07数值索引'!$A$5:$A$80,D6,'07数值索引'!$P$5:$P$80)+SUMIF('07数值索引'!$A$5:$A$80,E6,'07数值索引'!$P$5:$P$80)+SUMIF('07数值索引'!$A$5:$A$80,F6,'07数值索引'!$P$5:$P$80)+SUMIF('07数值索引'!$A$5:$A$80,G6,'07数值索引'!$P$5:$P$80)+SUMIF('07数值索引'!$A$5:$A$80,H6,'07数值索引'!$P$5:$P$80)+SUMIF('07数值索引'!$A$5:$A$80,I6,'07数值索引'!$P$5:$P$80)+SUMIF('07数值索引'!$A$5:$A$80,J6,'07数值索引'!$P$5:$P$80)+SUMIF('07数值索引'!$A$5:$A$80,K6,'07数值索引'!$P$5:$P$80)+SUMIF('07数值索引'!$A$5:$A$80,L6,'07数值索引'!$P$5:$P$80)+SUMIF('07数值索引'!$A$5:$A$80,M6,'07数值索引'!$P$5:$P$80)+SUMIF('07数值索引'!$A$5:$A$80,N6,'07数值索引'!$P$5:$P$80) -> 0 | AB6: =0+SUMIF('07数值索引'!$A$5:$A$80,C6,'07数值索引'!$Q$5:$Q$80)+SUMIF('07数值索引'!$A$5:$A$80,D6,'07数值索引'!$Q$5:$Q$80)+SUMIF('07数值索引'!$A$5:$A$80,E6,'07数值索引'!$Q$5:$Q$80)+SUMIF('07数值索引'!$A$5:$A$80,F6,'07数值索引'!$Q$5:$Q$80)+SUMIF('07数值索引'!$A$5:$A$80,G6,'07数值索引'!$Q$5:$Q$80)+SUMIF('07数值索引'!$A$5:$A$80,H6,'07数值索引'!$Q$5:$Q$80)+SUMIF('07数值索引'!$A$5:$A$80,I6,'07数值索引'!$Q$5:$Q$80)+SUMIF('07数值索引'!$A$5:$A$80,J6,'07数值索引'!$Q$5:$Q$80)+SUMIF('07数值索引'!$A$5:$A$80,K6,'07数值索引'!$Q$5:$Q$80)+SUMIF('07数值索引'!$A$5:$A$80,L6,'07数值索引'!$Q$5:$Q$80)+SUMIF('07数值索引'!$A$5:$A$80,M6,'07数值索引'!$Q$5:$Q$80)+SUMIF('07数值索引'!$A$5:$A$80,N6,'07数值索引'!$Q$5:$Q$80) -> 0 | AC6: =0+SUMIF('07数值索引'!$A$5:$A$80,C6,'07数值索引'!$R$5:$R$80)+SUMIF('07数值索引'!$A$5:$A$80,D6,'07数值索引'!$R$5:$R$80)+SUMIF('07数值索引'!$A$5:$A$80,E6,'07数值索引'!$R$5:$R$80)+SUMIF('07数值索引'!$A$5:$A$80,F6,'07数值索引'!$R$5:$R$80)+SUMIF('07数值索引'!$A$5:$A$80,G6,'07数值索引'!$R$5:$R$80)+SUMIF('07数值索引'!$A$5:$A$80,H6,'07数值索引'!$R$5:$R$80)+SUMIF('07数值索引'!$A$5:$A$80,I6,'07数值索引'!$R$5:$R$80)+SUMIF('07数值索引'!$A$5:$A$80,J6,'07数值索引'!$R$5:$R$80)+SUMIF('07数值索引'!$A$5:$A$80,K6,'07数值索引'!$R$5:$R$80)+SUMIF('07数值索引'!$A$5:$A$80,L6,'07数值索引'!$R$5:$R$80)+SUMIF('07数值索引'!$A$5:$A$80,M6,'07数值索引'!$R$5:$R$80)+SUMIF('07数值索引'!$A$5:$A$80,N6,'07数值索引'!$R$5:$R$80) -> 0 | AD6: =IF(AC6>0,"《无名尸体》",IF(AND(Y6>0,R6>=6),"《证人之死》",IF(AND(AA6>0,R6>=8),"《最后一次神迹》",IF(AND(AB6>0,Q6<=-3,T6>=2,U6>0,W6>0,AH6="是"),"《审判》",IF(AND(AA6>0,P6>=5,V6>0),"《第二位圣女》",IF(AND(O6>=7,S6>=1,U6=0,P6<=4,OR(Q6>=4,Z6>0)),"《继续前行》","《逃避》")))))) -> 《继续前行》 | AE6: 《继续前行》 | AF6: =IF(AD6=AE6,"PASS","CHECK") -> PASS | AG6: 仓单与暗号验证渠道；不依赖阿禾原谅 | AH6: =IF(AND(O6<=0,T6>=2,U6=1),"是","否") -> 否 | AI6: =IF(AND(OR(C6="",COUNTIF('07数值索引'!$A$5:$A$80,C6)=1),OR(D6="",COUNTIF('07数值索引'!$A$5:$A$80,D6)=1),OR(E6="",COUNTIF('07数值索引'!$A$5:$A$80,E6)=1),OR(F6="",COUNTIF('07数值索引'!$A$5:$A$80,F6)=1),OR(G6="",COUNTIF('07数值索引'!$A$5:$A$80,G6)=1),OR(H6="",COUNTIF('07数值索引'!$A$5:$A$80,H6)=1),OR(I6="",COUNTIF('07数值索引'!$A$5:$A$80,I6)=1),OR(J6="",COUNTIF('07数值索引'!$A$5:$A$80,J6)=1),OR(K6="",COUNTIF('07数值索引'!$A$5:$A$80,K6)=1),OR(L6="",COUNTIF('07数值索引'!$A$5:$A$80,L6)=1),OR(M6="",COUNTIF('07数值索引'!$A$5:$A$80,M6)=1),OR(N6="",COUNTIF('07数值索引'!$A$5:$A$80,N6)=1)),"PASS","CHECK") -> PASS | AJ6: =IFERROR(VLOOKUP(A6,'08A前置合法性'!$X$5:$Z$20,3,FALSE),"CHECK") -> PASS | AK6: =IF(AND(AF6="PASS",AI6="PASS",AJ6="PASS"),"PASS","CHECK") -> PASS
